[2025-03-24 12:18:46,700][tensorflow][WARNING] - From /Users/livialestingi/PycharmProjects/NodeSelection/power_of_choice/power_of_choice/dataset.py:38: load (from tensorflow.python.data.experimental.ops.io) is deprecated and will be removed in a future version.
Instructions for updating:
Use `tf.data.Dataset.load(...)` instead.
[2025-03-24 12:18:47,510][flwr][INFO] - Starting Flower simulation, config: ServerConfig(num_rounds=20, round_timeout=None)
[2025-03-24 12:18:48,836][flwr][INFO] - Flower VCE: Ray initialized with resources: {'object_store_memory': 2147483648.0, 'memory': 16416858112.0, 'CPU': 8.0, 'node:127.0.0.1': 1.0, 'node:__internal_head__': 1.0}
[2025-03-24 12:18:48,836][flwr][INFO] - Flower VCE: Resources for each Virtual Client: {'num_cpus': 0.5, 'num_gpus': 0}
[2025-03-24 12:18:48,842][flwr][INFO] - Flower VCE: Creating VirtualClientEngineActorPool with 16 actors
[2025-03-24 12:18:48,843][flwr][INFO] - Initializing global parameters
[2025-03-24 12:18:48,843][flwr][INFO] - Requesting initial parameters from one random client
[2025-03-24 12:18:53,945][flwr][INFO] - Received initial parameters from one random client
[2025-03-24 12:18:53,945][flwr][INFO] - Evaluating initial parameters
[2025-03-24 12:18:55,066][flwr][INFO] - initial parameters (loss, other metrics): 2.305549144744873, {'accuracy': 0.10000000149011612}
[2025-03-24 12:18:55,066][flwr][INFO] - FL starting
[2025-03-24 12:18:57,842][flwr][INFO] - Server 1: selected clients
                ['8', '6', '4', '3', '5', '9', '0', '2', '1', '7'] for first phase evaluation.
[2025-03-24 12:18:57,842][flwr][DEBUG] - evaluate_first_phase 1: strategy sampled 10 clients (out of 10)
[2025-03-24 12:18:58,243][flwr][ERROR] - Traceback (most recent call last):
  File "/opt/anaconda3/envs/NodeSelection/lib/python3.10/site-packages/flwr/simulation/ray_transport/ray_client_proxy.py", line 140, in _submit_job
    res = self.actor_pool.get_client_result(self.cid, timeout)
  File "/opt/anaconda3/envs/NodeSelection/lib/python3.10/site-packages/flwr/simulation/ray_transport/ray_actor.py", line 402, in get_client_result
    return self._fetch_future_result(cid)
  File "/opt/anaconda3/envs/NodeSelection/lib/python3.10/site-packages/flwr/simulation/ray_transport/ray_actor.py", line 288, in _fetch_future_result
    res_cid, res = ray.get(future)  # type: (str, ClientRes)
  File "/opt/anaconda3/envs/NodeSelection/lib/python3.10/site-packages/ray/_private/auto_init_hook.py", line 21, in auto_init_wrapper
    return fn(*args, **kwargs)
  File "/opt/anaconda3/envs/NodeSelection/lib/python3.10/site-packages/ray/_private/client_mode_hook.py", line 103, in wrapper
    return func(*args, **kwargs)
  File "/opt/anaconda3/envs/NodeSelection/lib/python3.10/site-packages/ray/_private/worker.py", line 2771, in get
    values, debugger_breakpoint = worker.get_objects(object_refs, timeout=timeout)
  File "/opt/anaconda3/envs/NodeSelection/lib/python3.10/site-packages/ray/_private/worker.py", line 919, in get_objects
    raise value.as_instanceof_cause()
ray.exceptions.RayTaskError(ClientException): [36mray::DefaultActor.run()[39m (pid=15289, ip=127.0.0.1, actor_id=6e88e79ef1ee7334ee7f72e501000000, repr=<flwr.simulation.ray_transport.ray_actor.DefaultActor object at 0x14a780b50>)
  File "/opt/anaconda3/envs/NodeSelection/lib/python3.10/site-packages/flwr/simulation/ray_transport/ray_client_proxy.py", line 215, in evaluate
    return maybe_call_evaluate(
  File "/opt/anaconda3/envs/NodeSelection/lib/python3.10/site-packages/flwr/client/client.py", line 237, in maybe_call_evaluate
    return client.evaluate(evaluate_ins)
  File "/opt/anaconda3/envs/NodeSelection/lib/python3.10/site-packages/flwr/client/app.py", line 357, in _evaluate
    results = self.numpy_client.evaluate(parameters, ins.config)  # type: ignore
  File "/Users/livialestingi/PycharmProjects/NodeSelection/power_of_choice/power_of_choice/client_ecto.py", line 90, in evaluate
    idx = np.random.choice(len(x_entire), b, replace=False)
  File "mtrand.pyx", line 984, in numpy.random.mtrand.RandomState.choice
ValueError: Cannot take a larger sample than population when 'replace=False'

The above exception was the direct cause of the following exception:

[36mray::DefaultActor.run()[39m (pid=15289, ip=127.0.0.1, actor_id=6e88e79ef1ee7334ee7f72e501000000, repr=<flwr.simulation.ray_transport.ray_actor.DefaultActor object at 0x14a780b50>)
  File "/opt/anaconda3/envs/NodeSelection/lib/python3.10/site-packages/flwr/simulation/ray_transport/ray_actor.py", line 72, in run
    raise ClientException(str(message)) from ex
flwr.simulation.ray_transport.ray_actor.ClientException: 
>>>>>>>A ClientException occurred.('\n\tSomething went wrong when running your client workload.\n\tClient 0 crashed when the DefaultActor was running its workload.\n\tException triggered on the client side: Traceback (most recent call last):\n  File "/opt/anaconda3/envs/NodeSelection/lib/python3.10/site-packages/flwr/simulation/ray_transport/ray_actor.py", line 60, in run\n    job_results = job_fn()\n  File "/opt/anaconda3/envs/NodeSelection/lib/python3.10/site-packages/flwr/simulation/ray_transport/ray_client_proxy.py", line 215, in evaluate\n    return maybe_call_evaluate(\n  File "/opt/anaconda3/envs/NodeSelection/lib/python3.10/site-packages/flwr/client/client.py", line 237, in maybe_call_evaluate\n    return client.evaluate(evaluate_ins)\n  File "/opt/anaconda3/envs/NodeSelection/lib/python3.10/site-packages/flwr/client/app.py", line 357, in _evaluate\n    results = self.numpy_client.evaluate(parameters, ins.config)  # type: ignore\n  File "/Users/livialestingi/PycharmProjects/NodeSelection/power_of_choice/power_of_choice/client_ecto.py", line 90, in evaluate\n    idx = np.random.choice(len(x_entire), b, replace=False)\n  File "mtrand.pyx", line 984, in numpy.random.mtrand.RandomState.choice\nValueError: Cannot take a larger sample than population when \'replace=False\'\n',)

[2025-03-24 12:18:58,246][flwr][ERROR] - [36mray::DefaultActor.run()[39m (pid=15289, ip=127.0.0.1, actor_id=6e88e79ef1ee7334ee7f72e501000000, repr=<flwr.simulation.ray_transport.ray_actor.DefaultActor object at 0x14a780b50>)
  File "/opt/anaconda3/envs/NodeSelection/lib/python3.10/site-packages/flwr/simulation/ray_transport/ray_client_proxy.py", line 215, in evaluate
    return maybe_call_evaluate(
  File "/opt/anaconda3/envs/NodeSelection/lib/python3.10/site-packages/flwr/client/client.py", line 237, in maybe_call_evaluate
    return client.evaluate(evaluate_ins)
  File "/opt/anaconda3/envs/NodeSelection/lib/python3.10/site-packages/flwr/client/app.py", line 357, in _evaluate
    results = self.numpy_client.evaluate(parameters, ins.config)  # type: ignore
  File "/Users/livialestingi/PycharmProjects/NodeSelection/power_of_choice/power_of_choice/client_ecto.py", line 90, in evaluate
    idx = np.random.choice(len(x_entire), b, replace=False)
  File "mtrand.pyx", line 984, in numpy.random.mtrand.RandomState.choice
ValueError: Cannot take a larger sample than population when 'replace=False'

The above exception was the direct cause of the following exception:

[36mray::DefaultActor.run()[39m (pid=15289, ip=127.0.0.1, actor_id=6e88e79ef1ee7334ee7f72e501000000, repr=<flwr.simulation.ray_transport.ray_actor.DefaultActor object at 0x14a780b50>)
  File "/opt/anaconda3/envs/NodeSelection/lib/python3.10/site-packages/flwr/simulation/ray_transport/ray_actor.py", line 72, in run
    raise ClientException(str(message)) from ex
flwr.simulation.ray_transport.ray_actor.ClientException: 
>>>>>>>A ClientException occurred.('\n\tSomething went wrong when running your client workload.\n\tClient 0 crashed when the DefaultActor was running its workload.\n\tException triggered on the client side: Traceback (most recent call last):\n  File "/opt/anaconda3/envs/NodeSelection/lib/python3.10/site-packages/flwr/simulation/ray_transport/ray_actor.py", line 60, in run\n    job_results = job_fn()\n  File "/opt/anaconda3/envs/NodeSelection/lib/python3.10/site-packages/flwr/simulation/ray_transport/ray_client_proxy.py", line 215, in evaluate\n    return maybe_call_evaluate(\n  File "/opt/anaconda3/envs/NodeSelection/lib/python3.10/site-packages/flwr/client/client.py", line 237, in maybe_call_evaluate\n    return client.evaluate(evaluate_ins)\n  File "/opt/anaconda3/envs/NodeSelection/lib/python3.10/site-packages/flwr/client/app.py", line 357, in _evaluate\n    results = self.numpy_client.evaluate(parameters, ins.config)  # type: ignore\n  File "/Users/livialestingi/PycharmProjects/NodeSelection/power_of_choice/power_of_choice/client_ecto.py", line 90, in evaluate\n    idx = np.random.choice(len(x_entire), b, replace=False)\n  File "mtrand.pyx", line 984, in numpy.random.mtrand.RandomState.choice\nValueError: Cannot take a larger sample than population when \'replace=False\'\n',)
[2025-03-24 12:18:59,967][flwr][DEBUG] - evaluate_first_phase of round 1 received 9 results and 1 failures
[2025-03-24 12:18:59,967][flwr][INFO] - Server 1: about to sample 9 clients
[2025-03-24 12:18:59,967][flwr][INFO] - Round 1: selected clients
            ['7', '5', '1', '6', '8', '4', '2', '9', '3'] for fit.
[2025-03-24 12:18:59,968][flwr][DEBUG] - fit_round 1: strategy sampled 9 clients (out of 10)
[2025-03-24 12:19:17,697][flwr][DEBUG] - fit_round 1 received 9 results and 0 failures
[2025-03-24 12:19:18,765][flwr][INFO] - fit progress: (1, 2.385333299636841, {'accuracy': 0.10040000081062317}, 23.699200749993906)
[2025-03-24 12:19:18,765][flwr][DEBUG] - evaluate_round 1: strategy sampled 9 clients (out of 10)
[2025-03-24 12:19:20,792][flwr][DEBUG] - evaluate_round 1 received 9 results and 0 failures
[2025-03-24 12:19:20,793][flwr][WARNING] - No evaluate_metrics_aggregation_fn provided
[2025-03-24 12:19:23,587][flwr][INFO] - Server 2: selected clients
                ['2', '9', '1', '8', '6', '7', '5', '4', '3', '0'] for first phase evaluation.
[2025-03-24 12:19:23,587][flwr][DEBUG] - evaluate_first_phase 2: strategy sampled 10 clients (out of 10)
[2025-03-24 12:19:23,762][flwr][ERROR] - Traceback (most recent call last):
  File "/opt/anaconda3/envs/NodeSelection/lib/python3.10/site-packages/flwr/simulation/ray_transport/ray_client_proxy.py", line 140, in _submit_job
    res = self.actor_pool.get_client_result(self.cid, timeout)
  File "/opt/anaconda3/envs/NodeSelection/lib/python3.10/site-packages/flwr/simulation/ray_transport/ray_actor.py", line 402, in get_client_result
    return self._fetch_future_result(cid)
  File "/opt/anaconda3/envs/NodeSelection/lib/python3.10/site-packages/flwr/simulation/ray_transport/ray_actor.py", line 288, in _fetch_future_result
    res_cid, res = ray.get(future)  # type: (str, ClientRes)
  File "/opt/anaconda3/envs/NodeSelection/lib/python3.10/site-packages/ray/_private/auto_init_hook.py", line 21, in auto_init_wrapper
    return fn(*args, **kwargs)
  File "/opt/anaconda3/envs/NodeSelection/lib/python3.10/site-packages/ray/_private/client_mode_hook.py", line 103, in wrapper
    return func(*args, **kwargs)
  File "/opt/anaconda3/envs/NodeSelection/lib/python3.10/site-packages/ray/_private/worker.py", line 2771, in get
    values, debugger_breakpoint = worker.get_objects(object_refs, timeout=timeout)
  File "/opt/anaconda3/envs/NodeSelection/lib/python3.10/site-packages/ray/_private/worker.py", line 919, in get_objects
    raise value.as_instanceof_cause()
ray.exceptions.RayTaskError(ClientException): [36mray::DefaultActor.run()[39m (pid=15289, ip=127.0.0.1, actor_id=6e88e79ef1ee7334ee7f72e501000000, repr=<flwr.simulation.ray_transport.ray_actor.DefaultActor object at 0x14a780b50>)
  File "/opt/anaconda3/envs/NodeSelection/lib/python3.10/site-packages/flwr/simulation/ray_transport/ray_client_proxy.py", line 215, in evaluate
    return maybe_call_evaluate(
  File "/opt/anaconda3/envs/NodeSelection/lib/python3.10/site-packages/flwr/client/client.py", line 237, in maybe_call_evaluate
    return client.evaluate(evaluate_ins)
  File "/opt/anaconda3/envs/NodeSelection/lib/python3.10/site-packages/flwr/client/app.py", line 357, in _evaluate
    results = self.numpy_client.evaluate(parameters, ins.config)  # type: ignore
  File "/Users/livialestingi/PycharmProjects/NodeSelection/power_of_choice/power_of_choice/client_ecto.py", line 90, in evaluate
    idx = np.random.choice(len(x_entire), b, replace=False)
  File "mtrand.pyx", line 984, in numpy.random.mtrand.RandomState.choice
ValueError: Cannot take a larger sample than population when 'replace=False'

The above exception was the direct cause of the following exception:

[36mray::DefaultActor.run()[39m (pid=15289, ip=127.0.0.1, actor_id=6e88e79ef1ee7334ee7f72e501000000, repr=<flwr.simulation.ray_transport.ray_actor.DefaultActor object at 0x14a780b50>)
  File "/opt/anaconda3/envs/NodeSelection/lib/python3.10/site-packages/flwr/simulation/ray_transport/ray_actor.py", line 72, in run
    raise ClientException(str(message)) from ex
flwr.simulation.ray_transport.ray_actor.ClientException: 
>>>>>>>A ClientException occurred.('\n\tSomething went wrong when running your client workload.\n\tClient 0 crashed when the DefaultActor was running its workload.\n\tException triggered on the client side: Traceback (most recent call last):\n  File "/opt/anaconda3/envs/NodeSelection/lib/python3.10/site-packages/flwr/simulation/ray_transport/ray_actor.py", line 60, in run\n    job_results = job_fn()\n  File "/opt/anaconda3/envs/NodeSelection/lib/python3.10/site-packages/flwr/simulation/ray_transport/ray_client_proxy.py", line 215, in evaluate\n    return maybe_call_evaluate(\n  File "/opt/anaconda3/envs/NodeSelection/lib/python3.10/site-packages/flwr/client/client.py", line 237, in maybe_call_evaluate\n    return client.evaluate(evaluate_ins)\n  File "/opt/anaconda3/envs/NodeSelection/lib/python3.10/site-packages/flwr/client/app.py", line 357, in _evaluate\n    results = self.numpy_client.evaluate(parameters, ins.config)  # type: ignore\n  File "/Users/livialestingi/PycharmProjects/NodeSelection/power_of_choice/power_of_choice/client_ecto.py", line 90, in evaluate\n    idx = np.random.choice(len(x_entire), b, replace=False)\n  File "mtrand.pyx", line 984, in numpy.random.mtrand.RandomState.choice\nValueError: Cannot take a larger sample than population when \'replace=False\'\n',)

[2025-03-24 12:19:23,764][flwr][ERROR] - [36mray::DefaultActor.run()[39m (pid=15289, ip=127.0.0.1, actor_id=6e88e79ef1ee7334ee7f72e501000000, repr=<flwr.simulation.ray_transport.ray_actor.DefaultActor object at 0x14a780b50>)
  File "/opt/anaconda3/envs/NodeSelection/lib/python3.10/site-packages/flwr/simulation/ray_transport/ray_client_proxy.py", line 215, in evaluate
    return maybe_call_evaluate(
  File "/opt/anaconda3/envs/NodeSelection/lib/python3.10/site-packages/flwr/client/client.py", line 237, in maybe_call_evaluate
    return client.evaluate(evaluate_ins)
  File "/opt/anaconda3/envs/NodeSelection/lib/python3.10/site-packages/flwr/client/app.py", line 357, in _evaluate
    results = self.numpy_client.evaluate(parameters, ins.config)  # type: ignore
  File "/Users/livialestingi/PycharmProjects/NodeSelection/power_of_choice/power_of_choice/client_ecto.py", line 90, in evaluate
    idx = np.random.choice(len(x_entire), b, replace=False)
  File "mtrand.pyx", line 984, in numpy.random.mtrand.RandomState.choice
ValueError: Cannot take a larger sample than population when 'replace=False'

The above exception was the direct cause of the following exception:

[36mray::DefaultActor.run()[39m (pid=15289, ip=127.0.0.1, actor_id=6e88e79ef1ee7334ee7f72e501000000, repr=<flwr.simulation.ray_transport.ray_actor.DefaultActor object at 0x14a780b50>)
  File "/opt/anaconda3/envs/NodeSelection/lib/python3.10/site-packages/flwr/simulation/ray_transport/ray_actor.py", line 72, in run
    raise ClientException(str(message)) from ex
flwr.simulation.ray_transport.ray_actor.ClientException: 
>>>>>>>A ClientException occurred.('\n\tSomething went wrong when running your client workload.\n\tClient 0 crashed when the DefaultActor was running its workload.\n\tException triggered on the client side: Traceback (most recent call last):\n  File "/opt/anaconda3/envs/NodeSelection/lib/python3.10/site-packages/flwr/simulation/ray_transport/ray_actor.py", line 60, in run\n    job_results = job_fn()\n  File "/opt/anaconda3/envs/NodeSelection/lib/python3.10/site-packages/flwr/simulation/ray_transport/ray_client_proxy.py", line 215, in evaluate\n    return maybe_call_evaluate(\n  File "/opt/anaconda3/envs/NodeSelection/lib/python3.10/site-packages/flwr/client/client.py", line 237, in maybe_call_evaluate\n    return client.evaluate(evaluate_ins)\n  File "/opt/anaconda3/envs/NodeSelection/lib/python3.10/site-packages/flwr/client/app.py", line 357, in _evaluate\n    results = self.numpy_client.evaluate(parameters, ins.config)  # type: ignore\n  File "/Users/livialestingi/PycharmProjects/NodeSelection/power_of_choice/power_of_choice/client_ecto.py", line 90, in evaluate\n    idx = np.random.choice(len(x_entire), b, replace=False)\n  File "mtrand.pyx", line 984, in numpy.random.mtrand.RandomState.choice\nValueError: Cannot take a larger sample than population when \'replace=False\'\n',)
[2025-03-24 12:19:25,443][flwr][DEBUG] - evaluate_first_phase of round 2 received 9 results and 1 failures
[2025-03-24 12:19:25,443][flwr][INFO] - Server 2: about to sample 9 clients
[2025-03-24 12:19:25,443][flwr][INFO] - Round 2: selected clients
            ['9', '2', '3', '7', '6', '4', '1', '5', '8'] for fit.
[2025-03-24 12:19:25,443][flwr][DEBUG] - fit_round 2: strategy sampled 9 clients (out of 10)
[2025-03-24 12:19:42,440][flwr][DEBUG] - fit_round 2 received 9 results and 0 failures
[2025-03-24 12:19:43,499][flwr][INFO] - fit progress: (2, 2.0079753398895264, {'accuracy': 0.22509999573230743}, 48.43310249999922)
[2025-03-24 12:19:43,499][flwr][DEBUG] - evaluate_round 2: strategy sampled 9 clients (out of 10)
[2025-03-24 12:19:45,547][flwr][DEBUG] - evaluate_round 2 received 9 results and 0 failures
[2025-03-24 12:19:48,380][flwr][INFO] - Server 3: selected clients
                ['3', '5', '2', '7', '8', '1', '9', '4', '0', '6'] for first phase evaluation.
[2025-03-24 12:19:48,380][flwr][DEBUG] - evaluate_first_phase 3: strategy sampled 10 clients (out of 10)
[2025-03-24 12:19:48,600][flwr][ERROR] - Traceback (most recent call last):
  File "/opt/anaconda3/envs/NodeSelection/lib/python3.10/site-packages/flwr/simulation/ray_transport/ray_client_proxy.py", line 140, in _submit_job
    res = self.actor_pool.get_client_result(self.cid, timeout)
  File "/opt/anaconda3/envs/NodeSelection/lib/python3.10/site-packages/flwr/simulation/ray_transport/ray_actor.py", line 402, in get_client_result
    return self._fetch_future_result(cid)
  File "/opt/anaconda3/envs/NodeSelection/lib/python3.10/site-packages/flwr/simulation/ray_transport/ray_actor.py", line 288, in _fetch_future_result
    res_cid, res = ray.get(future)  # type: (str, ClientRes)
  File "/opt/anaconda3/envs/NodeSelection/lib/python3.10/site-packages/ray/_private/auto_init_hook.py", line 21, in auto_init_wrapper
    return fn(*args, **kwargs)
  File "/opt/anaconda3/envs/NodeSelection/lib/python3.10/site-packages/ray/_private/client_mode_hook.py", line 103, in wrapper
    return func(*args, **kwargs)
  File "/opt/anaconda3/envs/NodeSelection/lib/python3.10/site-packages/ray/_private/worker.py", line 2771, in get
    values, debugger_breakpoint = worker.get_objects(object_refs, timeout=timeout)
  File "/opt/anaconda3/envs/NodeSelection/lib/python3.10/site-packages/ray/_private/worker.py", line 919, in get_objects
    raise value.as_instanceof_cause()
ray.exceptions.RayTaskError(ClientException): [36mray::DefaultActor.run()[39m (pid=15291, ip=127.0.0.1, actor_id=5dbeb755feff7f475d2d71a901000000, repr=<flwr.simulation.ray_transport.ray_actor.DefaultActor object at 0x14437cb20>)
  File "/opt/anaconda3/envs/NodeSelection/lib/python3.10/site-packages/flwr/simulation/ray_transport/ray_client_proxy.py", line 215, in evaluate
    return maybe_call_evaluate(
  File "/opt/anaconda3/envs/NodeSelection/lib/python3.10/site-packages/flwr/client/client.py", line 237, in maybe_call_evaluate
    return client.evaluate(evaluate_ins)
  File "/opt/anaconda3/envs/NodeSelection/lib/python3.10/site-packages/flwr/client/app.py", line 357, in _evaluate
    results = self.numpy_client.evaluate(parameters, ins.config)  # type: ignore
  File "/Users/livialestingi/PycharmProjects/NodeSelection/power_of_choice/power_of_choice/client_ecto.py", line 90, in evaluate
    idx = np.random.choice(len(x_entire), b, replace=False)
  File "mtrand.pyx", line 984, in numpy.random.mtrand.RandomState.choice
ValueError: Cannot take a larger sample than population when 'replace=False'

The above exception was the direct cause of the following exception:

[36mray::DefaultActor.run()[39m (pid=15291, ip=127.0.0.1, actor_id=5dbeb755feff7f475d2d71a901000000, repr=<flwr.simulation.ray_transport.ray_actor.DefaultActor object at 0x14437cb20>)
  File "/opt/anaconda3/envs/NodeSelection/lib/python3.10/site-packages/flwr/simulation/ray_transport/ray_actor.py", line 72, in run
    raise ClientException(str(message)) from ex
flwr.simulation.ray_transport.ray_actor.ClientException: 
>>>>>>>A ClientException occurred.('\n\tSomething went wrong when running your client workload.\n\tClient 0 crashed when the DefaultActor was running its workload.\n\tException triggered on the client side: Traceback (most recent call last):\n  File "/opt/anaconda3/envs/NodeSelection/lib/python3.10/site-packages/flwr/simulation/ray_transport/ray_actor.py", line 60, in run\n    job_results = job_fn()\n  File "/opt/anaconda3/envs/NodeSelection/lib/python3.10/site-packages/flwr/simulation/ray_transport/ray_client_proxy.py", line 215, in evaluate\n    return maybe_call_evaluate(\n  File "/opt/anaconda3/envs/NodeSelection/lib/python3.10/site-packages/flwr/client/client.py", line 237, in maybe_call_evaluate\n    return client.evaluate(evaluate_ins)\n  File "/opt/anaconda3/envs/NodeSelection/lib/python3.10/site-packages/flwr/client/app.py", line 357, in _evaluate\n    results = self.numpy_client.evaluate(parameters, ins.config)  # type: ignore\n  File "/Users/livialestingi/PycharmProjects/NodeSelection/power_of_choice/power_of_choice/client_ecto.py", line 90, in evaluate\n    idx = np.random.choice(len(x_entire), b, replace=False)\n  File "mtrand.pyx", line 984, in numpy.random.mtrand.RandomState.choice\nValueError: Cannot take a larger sample than population when \'replace=False\'\n',)

[2025-03-24 12:19:48,601][flwr][ERROR] - [36mray::DefaultActor.run()[39m (pid=15291, ip=127.0.0.1, actor_id=5dbeb755feff7f475d2d71a901000000, repr=<flwr.simulation.ray_transport.ray_actor.DefaultActor object at 0x14437cb20>)
  File "/opt/anaconda3/envs/NodeSelection/lib/python3.10/site-packages/flwr/simulation/ray_transport/ray_client_proxy.py", line 215, in evaluate
    return maybe_call_evaluate(
  File "/opt/anaconda3/envs/NodeSelection/lib/python3.10/site-packages/flwr/client/client.py", line 237, in maybe_call_evaluate
    return client.evaluate(evaluate_ins)
  File "/opt/anaconda3/envs/NodeSelection/lib/python3.10/site-packages/flwr/client/app.py", line 357, in _evaluate
    results = self.numpy_client.evaluate(parameters, ins.config)  # type: ignore
  File "/Users/livialestingi/PycharmProjects/NodeSelection/power_of_choice/power_of_choice/client_ecto.py", line 90, in evaluate
    idx = np.random.choice(len(x_entire), b, replace=False)
  File "mtrand.pyx", line 984, in numpy.random.mtrand.RandomState.choice
ValueError: Cannot take a larger sample than population when 'replace=False'

The above exception was the direct cause of the following exception:

[36mray::DefaultActor.run()[39m (pid=15291, ip=127.0.0.1, actor_id=5dbeb755feff7f475d2d71a901000000, repr=<flwr.simulation.ray_transport.ray_actor.DefaultActor object at 0x14437cb20>)
  File "/opt/anaconda3/envs/NodeSelection/lib/python3.10/site-packages/flwr/simulation/ray_transport/ray_actor.py", line 72, in run
    raise ClientException(str(message)) from ex
flwr.simulation.ray_transport.ray_actor.ClientException: 
>>>>>>>A ClientException occurred.('\n\tSomething went wrong when running your client workload.\n\tClient 0 crashed when the DefaultActor was running its workload.\n\tException triggered on the client side: Traceback (most recent call last):\n  File "/opt/anaconda3/envs/NodeSelection/lib/python3.10/site-packages/flwr/simulation/ray_transport/ray_actor.py", line 60, in run\n    job_results = job_fn()\n  File "/opt/anaconda3/envs/NodeSelection/lib/python3.10/site-packages/flwr/simulation/ray_transport/ray_client_proxy.py", line 215, in evaluate\n    return maybe_call_evaluate(\n  File "/opt/anaconda3/envs/NodeSelection/lib/python3.10/site-packages/flwr/client/client.py", line 237, in maybe_call_evaluate\n    return client.evaluate(evaluate_ins)\n  File "/opt/anaconda3/envs/NodeSelection/lib/python3.10/site-packages/flwr/client/app.py", line 357, in _evaluate\n    results = self.numpy_client.evaluate(parameters, ins.config)  # type: ignore\n  File "/Users/livialestingi/PycharmProjects/NodeSelection/power_of_choice/power_of_choice/client_ecto.py", line 90, in evaluate\n    idx = np.random.choice(len(x_entire), b, replace=False)\n  File "mtrand.pyx", line 984, in numpy.random.mtrand.RandomState.choice\nValueError: Cannot take a larger sample than population when \'replace=False\'\n',)
[2025-03-24 12:19:50,261][flwr][DEBUG] - evaluate_first_phase of round 3 received 9 results and 1 failures
[2025-03-24 12:19:50,262][flwr][INFO] - Server 3: about to sample 9 clients
[2025-03-24 12:19:50,262][flwr][INFO] - Round 3: selected clients
            ['6', '2', '5', '4', '8', '3', '1', '7', '9'] for fit.
[2025-03-24 12:19:50,262][flwr][DEBUG] - fit_round 3: strategy sampled 9 clients (out of 10)
[2025-03-24 12:20:07,370][flwr][DEBUG] - fit_round 3 received 9 results and 0 failures
[2025-03-24 12:20:08,390][flwr][INFO] - fit progress: (3, 1.6786978244781494, {'accuracy': 0.3880000114440918}, 73.32388987499871)
[2025-03-24 12:20:08,390][flwr][DEBUG] - evaluate_round 3: strategy sampled 9 clients (out of 10)
[2025-03-24 12:20:10,425][flwr][DEBUG] - evaluate_round 3 received 9 results and 0 failures
[2025-03-24 12:20:13,268][flwr][INFO] - Server 4: selected clients
                ['4', '1', '2', '8', '6', '3', '7', '5', '9', '0'] for first phase evaluation.
[2025-03-24 12:20:13,268][flwr][DEBUG] - evaluate_first_phase 4: strategy sampled 10 clients (out of 10)
[2025-03-24 12:20:13,464][flwr][ERROR] - Traceback (most recent call last):
  File "/opt/anaconda3/envs/NodeSelection/lib/python3.10/site-packages/flwr/simulation/ray_transport/ray_client_proxy.py", line 140, in _submit_job
    res = self.actor_pool.get_client_result(self.cid, timeout)
  File "/opt/anaconda3/envs/NodeSelection/lib/python3.10/site-packages/flwr/simulation/ray_transport/ray_actor.py", line 402, in get_client_result
    return self._fetch_future_result(cid)
  File "/opt/anaconda3/envs/NodeSelection/lib/python3.10/site-packages/flwr/simulation/ray_transport/ray_actor.py", line 288, in _fetch_future_result
    res_cid, res = ray.get(future)  # type: (str, ClientRes)
  File "/opt/anaconda3/envs/NodeSelection/lib/python3.10/site-packages/ray/_private/auto_init_hook.py", line 21, in auto_init_wrapper
    return fn(*args, **kwargs)
  File "/opt/anaconda3/envs/NodeSelection/lib/python3.10/site-packages/ray/_private/client_mode_hook.py", line 103, in wrapper
    return func(*args, **kwargs)
  File "/opt/anaconda3/envs/NodeSelection/lib/python3.10/site-packages/ray/_private/worker.py", line 2771, in get
    values, debugger_breakpoint = worker.get_objects(object_refs, timeout=timeout)
  File "/opt/anaconda3/envs/NodeSelection/lib/python3.10/site-packages/ray/_private/worker.py", line 919, in get_objects
    raise value.as_instanceof_cause()
ray.exceptions.RayTaskError(ClientException): [36mray::DefaultActor.run()[39m (pid=15291, ip=127.0.0.1, actor_id=5dbeb755feff7f475d2d71a901000000, repr=<flwr.simulation.ray_transport.ray_actor.DefaultActor object at 0x14437cb20>)
  File "/opt/anaconda3/envs/NodeSelection/lib/python3.10/site-packages/flwr/simulation/ray_transport/ray_client_proxy.py", line 215, in evaluate
    return maybe_call_evaluate(
  File "/opt/anaconda3/envs/NodeSelection/lib/python3.10/site-packages/flwr/client/client.py", line 237, in maybe_call_evaluate
    return client.evaluate(evaluate_ins)
  File "/opt/anaconda3/envs/NodeSelection/lib/python3.10/site-packages/flwr/client/app.py", line 357, in _evaluate
    results = self.numpy_client.evaluate(parameters, ins.config)  # type: ignore
  File "/Users/livialestingi/PycharmProjects/NodeSelection/power_of_choice/power_of_choice/client_ecto.py", line 90, in evaluate
    idx = np.random.choice(len(x_entire), b, replace=False)
  File "mtrand.pyx", line 984, in numpy.random.mtrand.RandomState.choice
ValueError: Cannot take a larger sample than population when 'replace=False'

The above exception was the direct cause of the following exception:

[36mray::DefaultActor.run()[39m (pid=15291, ip=127.0.0.1, actor_id=5dbeb755feff7f475d2d71a901000000, repr=<flwr.simulation.ray_transport.ray_actor.DefaultActor object at 0x14437cb20>)
  File "/opt/anaconda3/envs/NodeSelection/lib/python3.10/site-packages/flwr/simulation/ray_transport/ray_actor.py", line 72, in run
    raise ClientException(str(message)) from ex
flwr.simulation.ray_transport.ray_actor.ClientException: 
>>>>>>>A ClientException occurred.('\n\tSomething went wrong when running your client workload.\n\tClient 0 crashed when the DefaultActor was running its workload.\n\tException triggered on the client side: Traceback (most recent call last):\n  File "/opt/anaconda3/envs/NodeSelection/lib/python3.10/site-packages/flwr/simulation/ray_transport/ray_actor.py", line 60, in run\n    job_results = job_fn()\n  File "/opt/anaconda3/envs/NodeSelection/lib/python3.10/site-packages/flwr/simulation/ray_transport/ray_client_proxy.py", line 215, in evaluate\n    return maybe_call_evaluate(\n  File "/opt/anaconda3/envs/NodeSelection/lib/python3.10/site-packages/flwr/client/client.py", line 237, in maybe_call_evaluate\n    return client.evaluate(evaluate_ins)\n  File "/opt/anaconda3/envs/NodeSelection/lib/python3.10/site-packages/flwr/client/app.py", line 357, in _evaluate\n    results = self.numpy_client.evaluate(parameters, ins.config)  # type: ignore\n  File "/Users/livialestingi/PycharmProjects/NodeSelection/power_of_choice/power_of_choice/client_ecto.py", line 90, in evaluate\n    idx = np.random.choice(len(x_entire), b, replace=False)\n  File "mtrand.pyx", line 984, in numpy.random.mtrand.RandomState.choice\nValueError: Cannot take a larger sample than population when \'replace=False\'\n',)

[2025-03-24 12:20:13,466][flwr][ERROR] - [36mray::DefaultActor.run()[39m (pid=15291, ip=127.0.0.1, actor_id=5dbeb755feff7f475d2d71a901000000, repr=<flwr.simulation.ray_transport.ray_actor.DefaultActor object at 0x14437cb20>)
  File "/opt/anaconda3/envs/NodeSelection/lib/python3.10/site-packages/flwr/simulation/ray_transport/ray_client_proxy.py", line 215, in evaluate
    return maybe_call_evaluate(
  File "/opt/anaconda3/envs/NodeSelection/lib/python3.10/site-packages/flwr/client/client.py", line 237, in maybe_call_evaluate
    return client.evaluate(evaluate_ins)
  File "/opt/anaconda3/envs/NodeSelection/lib/python3.10/site-packages/flwr/client/app.py", line 357, in _evaluate
    results = self.numpy_client.evaluate(parameters, ins.config)  # type: ignore
  File "/Users/livialestingi/PycharmProjects/NodeSelection/power_of_choice/power_of_choice/client_ecto.py", line 90, in evaluate
    idx = np.random.choice(len(x_entire), b, replace=False)
  File "mtrand.pyx", line 984, in numpy.random.mtrand.RandomState.choice
ValueError: Cannot take a larger sample than population when 'replace=False'

The above exception was the direct cause of the following exception:

[36mray::DefaultActor.run()[39m (pid=15291, ip=127.0.0.1, actor_id=5dbeb755feff7f475d2d71a901000000, repr=<flwr.simulation.ray_transport.ray_actor.DefaultActor object at 0x14437cb20>)
  File "/opt/anaconda3/envs/NodeSelection/lib/python3.10/site-packages/flwr/simulation/ray_transport/ray_actor.py", line 72, in run
    raise ClientException(str(message)) from ex
flwr.simulation.ray_transport.ray_actor.ClientException: 
>>>>>>>A ClientException occurred.('\n\tSomething went wrong when running your client workload.\n\tClient 0 crashed when the DefaultActor was running its workload.\n\tException triggered on the client side: Traceback (most recent call last):\n  File "/opt/anaconda3/envs/NodeSelection/lib/python3.10/site-packages/flwr/simulation/ray_transport/ray_actor.py", line 60, in run\n    job_results = job_fn()\n  File "/opt/anaconda3/envs/NodeSelection/lib/python3.10/site-packages/flwr/simulation/ray_transport/ray_client_proxy.py", line 215, in evaluate\n    return maybe_call_evaluate(\n  File "/opt/anaconda3/envs/NodeSelection/lib/python3.10/site-packages/flwr/client/client.py", line 237, in maybe_call_evaluate\n    return client.evaluate(evaluate_ins)\n  File "/opt/anaconda3/envs/NodeSelection/lib/python3.10/site-packages/flwr/client/app.py", line 357, in _evaluate\n    results = self.numpy_client.evaluate(parameters, ins.config)  # type: ignore\n  File "/Users/livialestingi/PycharmProjects/NodeSelection/power_of_choice/power_of_choice/client_ecto.py", line 90, in evaluate\n    idx = np.random.choice(len(x_entire), b, replace=False)\n  File "mtrand.pyx", line 984, in numpy.random.mtrand.RandomState.choice\nValueError: Cannot take a larger sample than population when \'replace=False\'\n',)
[2025-03-24 12:20:15,187][flwr][DEBUG] - evaluate_first_phase of round 4 received 9 results and 1 failures
[2025-03-24 12:20:15,187][flwr][INFO] - Server 4: about to sample 9 clients
[2025-03-24 12:20:15,187][flwr][INFO] - Round 4: selected clients
            ['6', '8', '2', '9', '5', '3', '1', '7', '4'] for fit.
[2025-03-24 12:20:15,187][flwr][DEBUG] - fit_round 4: strategy sampled 9 clients (out of 10)
[2025-03-24 12:20:32,924][flwr][DEBUG] - fit_round 4 received 9 results and 0 failures
[2025-03-24 12:20:33,953][flwr][INFO] - fit progress: (4, 2.144805669784546, {'accuracy': 0.23160000145435333}, 98.88757395799621)
[2025-03-24 12:20:33,954][flwr][DEBUG] - evaluate_round 4: strategy sampled 9 clients (out of 10)
[2025-03-24 12:20:36,018][flwr][DEBUG] - evaluate_round 4 received 9 results and 0 failures
[2025-03-24 12:20:38,800][flwr][INFO] - Server 5: selected clients
                ['0', '4', '7', '2', '9', '6', '5', '8', '1', '3'] for first phase evaluation.
[2025-03-24 12:20:38,800][flwr][DEBUG] - evaluate_first_phase 5: strategy sampled 10 clients (out of 10)
[2025-03-24 12:20:38,965][flwr][ERROR] - Traceback (most recent call last):
  File "/opt/anaconda3/envs/NodeSelection/lib/python3.10/site-packages/flwr/simulation/ray_transport/ray_client_proxy.py", line 140, in _submit_job
    res = self.actor_pool.get_client_result(self.cid, timeout)
  File "/opt/anaconda3/envs/NodeSelection/lib/python3.10/site-packages/flwr/simulation/ray_transport/ray_actor.py", line 402, in get_client_result
    return self._fetch_future_result(cid)
  File "/opt/anaconda3/envs/NodeSelection/lib/python3.10/site-packages/flwr/simulation/ray_transport/ray_actor.py", line 288, in _fetch_future_result
    res_cid, res = ray.get(future)  # type: (str, ClientRes)
  File "/opt/anaconda3/envs/NodeSelection/lib/python3.10/site-packages/ray/_private/auto_init_hook.py", line 21, in auto_init_wrapper
    return fn(*args, **kwargs)
  File "/opt/anaconda3/envs/NodeSelection/lib/python3.10/site-packages/ray/_private/client_mode_hook.py", line 103, in wrapper
    return func(*args, **kwargs)
  File "/opt/anaconda3/envs/NodeSelection/lib/python3.10/site-packages/ray/_private/worker.py", line 2771, in get
    values, debugger_breakpoint = worker.get_objects(object_refs, timeout=timeout)
  File "/opt/anaconda3/envs/NodeSelection/lib/python3.10/site-packages/ray/_private/worker.py", line 919, in get_objects
    raise value.as_instanceof_cause()
ray.exceptions.RayTaskError(ClientException): [36mray::DefaultActor.run()[39m (pid=15284, ip=127.0.0.1, actor_id=948692ce9fb9c1e8140f598a01000000, repr=<flwr.simulation.ray_transport.ray_actor.DefaultActor object at 0x13a480a60>)
  File "/opt/anaconda3/envs/NodeSelection/lib/python3.10/site-packages/flwr/simulation/ray_transport/ray_client_proxy.py", line 215, in evaluate
    return maybe_call_evaluate(
  File "/opt/anaconda3/envs/NodeSelection/lib/python3.10/site-packages/flwr/client/client.py", line 237, in maybe_call_evaluate
    return client.evaluate(evaluate_ins)
  File "/opt/anaconda3/envs/NodeSelection/lib/python3.10/site-packages/flwr/client/app.py", line 357, in _evaluate
    results = self.numpy_client.evaluate(parameters, ins.config)  # type: ignore
  File "/Users/livialestingi/PycharmProjects/NodeSelection/power_of_choice/power_of_choice/client_ecto.py", line 90, in evaluate
    idx = np.random.choice(len(x_entire), b, replace=False)
  File "mtrand.pyx", line 984, in numpy.random.mtrand.RandomState.choice
ValueError: Cannot take a larger sample than population when 'replace=False'

The above exception was the direct cause of the following exception:

[36mray::DefaultActor.run()[39m (pid=15284, ip=127.0.0.1, actor_id=948692ce9fb9c1e8140f598a01000000, repr=<flwr.simulation.ray_transport.ray_actor.DefaultActor object at 0x13a480a60>)
  File "/opt/anaconda3/envs/NodeSelection/lib/python3.10/site-packages/flwr/simulation/ray_transport/ray_actor.py", line 72, in run
    raise ClientException(str(message)) from ex
flwr.simulation.ray_transport.ray_actor.ClientException: 
>>>>>>>A ClientException occurred.('\n\tSomething went wrong when running your client workload.\n\tClient 0 crashed when the DefaultActor was running its workload.\n\tException triggered on the client side: Traceback (most recent call last):\n  File "/opt/anaconda3/envs/NodeSelection/lib/python3.10/site-packages/flwr/simulation/ray_transport/ray_actor.py", line 60, in run\n    job_results = job_fn()\n  File "/opt/anaconda3/envs/NodeSelection/lib/python3.10/site-packages/flwr/simulation/ray_transport/ray_client_proxy.py", line 215, in evaluate\n    return maybe_call_evaluate(\n  File "/opt/anaconda3/envs/NodeSelection/lib/python3.10/site-packages/flwr/client/client.py", line 237, in maybe_call_evaluate\n    return client.evaluate(evaluate_ins)\n  File "/opt/anaconda3/envs/NodeSelection/lib/python3.10/site-packages/flwr/client/app.py", line 357, in _evaluate\n    results = self.numpy_client.evaluate(parameters, ins.config)  # type: ignore\n  File "/Users/livialestingi/PycharmProjects/NodeSelection/power_of_choice/power_of_choice/client_ecto.py", line 90, in evaluate\n    idx = np.random.choice(len(x_entire), b, replace=False)\n  File "mtrand.pyx", line 984, in numpy.random.mtrand.RandomState.choice\nValueError: Cannot take a larger sample than population when \'replace=False\'\n',)

[2025-03-24 12:20:38,967][flwr][ERROR] - [36mray::DefaultActor.run()[39m (pid=15284, ip=127.0.0.1, actor_id=948692ce9fb9c1e8140f598a01000000, repr=<flwr.simulation.ray_transport.ray_actor.DefaultActor object at 0x13a480a60>)
  File "/opt/anaconda3/envs/NodeSelection/lib/python3.10/site-packages/flwr/simulation/ray_transport/ray_client_proxy.py", line 215, in evaluate
    return maybe_call_evaluate(
  File "/opt/anaconda3/envs/NodeSelection/lib/python3.10/site-packages/flwr/client/client.py", line 237, in maybe_call_evaluate
    return client.evaluate(evaluate_ins)
  File "/opt/anaconda3/envs/NodeSelection/lib/python3.10/site-packages/flwr/client/app.py", line 357, in _evaluate
    results = self.numpy_client.evaluate(parameters, ins.config)  # type: ignore
  File "/Users/livialestingi/PycharmProjects/NodeSelection/power_of_choice/power_of_choice/client_ecto.py", line 90, in evaluate
    idx = np.random.choice(len(x_entire), b, replace=False)
  File "mtrand.pyx", line 984, in numpy.random.mtrand.RandomState.choice
ValueError: Cannot take a larger sample than population when 'replace=False'

The above exception was the direct cause of the following exception:

[36mray::DefaultActor.run()[39m (pid=15284, ip=127.0.0.1, actor_id=948692ce9fb9c1e8140f598a01000000, repr=<flwr.simulation.ray_transport.ray_actor.DefaultActor object at 0x13a480a60>)
  File "/opt/anaconda3/envs/NodeSelection/lib/python3.10/site-packages/flwr/simulation/ray_transport/ray_actor.py", line 72, in run
    raise ClientException(str(message)) from ex
flwr.simulation.ray_transport.ray_actor.ClientException: 
>>>>>>>A ClientException occurred.('\n\tSomething went wrong when running your client workload.\n\tClient 0 crashed when the DefaultActor was running its workload.\n\tException triggered on the client side: Traceback (most recent call last):\n  File "/opt/anaconda3/envs/NodeSelection/lib/python3.10/site-packages/flwr/simulation/ray_transport/ray_actor.py", line 60, in run\n    job_results = job_fn()\n  File "/opt/anaconda3/envs/NodeSelection/lib/python3.10/site-packages/flwr/simulation/ray_transport/ray_client_proxy.py", line 215, in evaluate\n    return maybe_call_evaluate(\n  File "/opt/anaconda3/envs/NodeSelection/lib/python3.10/site-packages/flwr/client/client.py", line 237, in maybe_call_evaluate\n    return client.evaluate(evaluate_ins)\n  File "/opt/anaconda3/envs/NodeSelection/lib/python3.10/site-packages/flwr/client/app.py", line 357, in _evaluate\n    results = self.numpy_client.evaluate(parameters, ins.config)  # type: ignore\n  File "/Users/livialestingi/PycharmProjects/NodeSelection/power_of_choice/power_of_choice/client_ecto.py", line 90, in evaluate\n    idx = np.random.choice(len(x_entire), b, replace=False)\n  File "mtrand.pyx", line 984, in numpy.random.mtrand.RandomState.choice\nValueError: Cannot take a larger sample than population when \'replace=False\'\n',)
[2025-03-24 12:20:40,734][flwr][DEBUG] - evaluate_first_phase of round 5 received 9 results and 1 failures
[2025-03-24 12:20:40,734][flwr][INFO] - Server 5: about to sample 9 clients
[2025-03-24 12:20:40,734][flwr][INFO] - Round 5: selected clients
            ['6', '7', '2', '5', '1', '8', '4', '3', '9'] for fit.
[2025-03-24 12:20:40,734][flwr][DEBUG] - fit_round 5: strategy sampled 9 clients (out of 10)
[2025-03-24 12:20:58,469][flwr][DEBUG] - fit_round 5 received 9 results and 0 failures
[2025-03-24 12:20:59,510][flwr][INFO] - fit progress: (5, 1.8693904876708984, {'accuracy': 0.3174999952316284}, 124.44437595799536)
[2025-03-24 12:20:59,510][flwr][DEBUG] - evaluate_round 5: strategy sampled 9 clients (out of 10)
[2025-03-24 12:21:01,658][flwr][DEBUG] - evaluate_round 5 received 9 results and 0 failures
[2025-03-24 12:21:04,470][flwr][INFO] - Server 6: selected clients
                ['3', '1', '9', '5', '8', '6', '7', '2', '4', '0'] for first phase evaluation.
[2025-03-24 12:21:04,470][flwr][DEBUG] - evaluate_first_phase 6: strategy sampled 10 clients (out of 10)
[2025-03-24 12:21:04,645][flwr][ERROR] - Traceback (most recent call last):
  File "/opt/anaconda3/envs/NodeSelection/lib/python3.10/site-packages/flwr/simulation/ray_transport/ray_client_proxy.py", line 140, in _submit_job
    res = self.actor_pool.get_client_result(self.cid, timeout)
  File "/opt/anaconda3/envs/NodeSelection/lib/python3.10/site-packages/flwr/simulation/ray_transport/ray_actor.py", line 402, in get_client_result
    return self._fetch_future_result(cid)
  File "/opt/anaconda3/envs/NodeSelection/lib/python3.10/site-packages/flwr/simulation/ray_transport/ray_actor.py", line 288, in _fetch_future_result
    res_cid, res = ray.get(future)  # type: (str, ClientRes)
  File "/opt/anaconda3/envs/NodeSelection/lib/python3.10/site-packages/ray/_private/auto_init_hook.py", line 21, in auto_init_wrapper
    return fn(*args, **kwargs)
  File "/opt/anaconda3/envs/NodeSelection/lib/python3.10/site-packages/ray/_private/client_mode_hook.py", line 103, in wrapper
    return func(*args, **kwargs)
  File "/opt/anaconda3/envs/NodeSelection/lib/python3.10/site-packages/ray/_private/worker.py", line 2771, in get
    values, debugger_breakpoint = worker.get_objects(object_refs, timeout=timeout)
  File "/opt/anaconda3/envs/NodeSelection/lib/python3.10/site-packages/ray/_private/worker.py", line 919, in get_objects
    raise value.as_instanceof_cause()
ray.exceptions.RayTaskError(ClientException): [36mray::DefaultActor.run()[39m (pid=15284, ip=127.0.0.1, actor_id=948692ce9fb9c1e8140f598a01000000, repr=<flwr.simulation.ray_transport.ray_actor.DefaultActor object at 0x13a480a60>)
  File "/opt/anaconda3/envs/NodeSelection/lib/python3.10/site-packages/flwr/simulation/ray_transport/ray_client_proxy.py", line 215, in evaluate
    return maybe_call_evaluate(
  File "/opt/anaconda3/envs/NodeSelection/lib/python3.10/site-packages/flwr/client/client.py", line 237, in maybe_call_evaluate
    return client.evaluate(evaluate_ins)
  File "/opt/anaconda3/envs/NodeSelection/lib/python3.10/site-packages/flwr/client/app.py", line 357, in _evaluate
    results = self.numpy_client.evaluate(parameters, ins.config)  # type: ignore
  File "/Users/livialestingi/PycharmProjects/NodeSelection/power_of_choice/power_of_choice/client_ecto.py", line 90, in evaluate
    idx = np.random.choice(len(x_entire), b, replace=False)
  File "mtrand.pyx", line 984, in numpy.random.mtrand.RandomState.choice
ValueError: Cannot take a larger sample than population when 'replace=False'

The above exception was the direct cause of the following exception:

[36mray::DefaultActor.run()[39m (pid=15284, ip=127.0.0.1, actor_id=948692ce9fb9c1e8140f598a01000000, repr=<flwr.simulation.ray_transport.ray_actor.DefaultActor object at 0x13a480a60>)
  File "/opt/anaconda3/envs/NodeSelection/lib/python3.10/site-packages/flwr/simulation/ray_transport/ray_actor.py", line 72, in run
    raise ClientException(str(message)) from ex
flwr.simulation.ray_transport.ray_actor.ClientException: 
>>>>>>>A ClientException occurred.('\n\tSomething went wrong when running your client workload.\n\tClient 0 crashed when the DefaultActor was running its workload.\n\tException triggered on the client side: Traceback (most recent call last):\n  File "/opt/anaconda3/envs/NodeSelection/lib/python3.10/site-packages/flwr/simulation/ray_transport/ray_actor.py", line 60, in run\n    job_results = job_fn()\n  File "/opt/anaconda3/envs/NodeSelection/lib/python3.10/site-packages/flwr/simulation/ray_transport/ray_client_proxy.py", line 215, in evaluate\n    return maybe_call_evaluate(\n  File "/opt/anaconda3/envs/NodeSelection/lib/python3.10/site-packages/flwr/client/client.py", line 237, in maybe_call_evaluate\n    return client.evaluate(evaluate_ins)\n  File "/opt/anaconda3/envs/NodeSelection/lib/python3.10/site-packages/flwr/client/app.py", line 357, in _evaluate\n    results = self.numpy_client.evaluate(parameters, ins.config)  # type: ignore\n  File "/Users/livialestingi/PycharmProjects/NodeSelection/power_of_choice/power_of_choice/client_ecto.py", line 90, in evaluate\n    idx = np.random.choice(len(x_entire), b, replace=False)\n  File "mtrand.pyx", line 984, in numpy.random.mtrand.RandomState.choice\nValueError: Cannot take a larger sample than population when \'replace=False\'\n',)

[2025-03-24 12:21:04,648][flwr][ERROR] - [36mray::DefaultActor.run()[39m (pid=15284, ip=127.0.0.1, actor_id=948692ce9fb9c1e8140f598a01000000, repr=<flwr.simulation.ray_transport.ray_actor.DefaultActor object at 0x13a480a60>)
  File "/opt/anaconda3/envs/NodeSelection/lib/python3.10/site-packages/flwr/simulation/ray_transport/ray_client_proxy.py", line 215, in evaluate
    return maybe_call_evaluate(
  File "/opt/anaconda3/envs/NodeSelection/lib/python3.10/site-packages/flwr/client/client.py", line 237, in maybe_call_evaluate
    return client.evaluate(evaluate_ins)
  File "/opt/anaconda3/envs/NodeSelection/lib/python3.10/site-packages/flwr/client/app.py", line 357, in _evaluate
    results = self.numpy_client.evaluate(parameters, ins.config)  # type: ignore
  File "/Users/livialestingi/PycharmProjects/NodeSelection/power_of_choice/power_of_choice/client_ecto.py", line 90, in evaluate
    idx = np.random.choice(len(x_entire), b, replace=False)
  File "mtrand.pyx", line 984, in numpy.random.mtrand.RandomState.choice
ValueError: Cannot take a larger sample than population when 'replace=False'

The above exception was the direct cause of the following exception:

[36mray::DefaultActor.run()[39m (pid=15284, ip=127.0.0.1, actor_id=948692ce9fb9c1e8140f598a01000000, repr=<flwr.simulation.ray_transport.ray_actor.DefaultActor object at 0x13a480a60>)
  File "/opt/anaconda3/envs/NodeSelection/lib/python3.10/site-packages/flwr/simulation/ray_transport/ray_actor.py", line 72, in run
    raise ClientException(str(message)) from ex
flwr.simulation.ray_transport.ray_actor.ClientException: 
>>>>>>>A ClientException occurred.('\n\tSomething went wrong when running your client workload.\n\tClient 0 crashed when the DefaultActor was running its workload.\n\tException triggered on the client side: Traceback (most recent call last):\n  File "/opt/anaconda3/envs/NodeSelection/lib/python3.10/site-packages/flwr/simulation/ray_transport/ray_actor.py", line 60, in run\n    job_results = job_fn()\n  File "/opt/anaconda3/envs/NodeSelection/lib/python3.10/site-packages/flwr/simulation/ray_transport/ray_client_proxy.py", line 215, in evaluate\n    return maybe_call_evaluate(\n  File "/opt/anaconda3/envs/NodeSelection/lib/python3.10/site-packages/flwr/client/client.py", line 237, in maybe_call_evaluate\n    return client.evaluate(evaluate_ins)\n  File "/opt/anaconda3/envs/NodeSelection/lib/python3.10/site-packages/flwr/client/app.py", line 357, in _evaluate\n    results = self.numpy_client.evaluate(parameters, ins.config)  # type: ignore\n  File "/Users/livialestingi/PycharmProjects/NodeSelection/power_of_choice/power_of_choice/client_ecto.py", line 90, in evaluate\n    idx = np.random.choice(len(x_entire), b, replace=False)\n  File "mtrand.pyx", line 984, in numpy.random.mtrand.RandomState.choice\nValueError: Cannot take a larger sample than population when \'replace=False\'\n',)
[2025-03-24 12:21:06,441][flwr][DEBUG] - evaluate_first_phase of round 6 received 9 results and 1 failures
[2025-03-24 12:21:06,441][flwr][INFO] - Server 6: about to sample 9 clients
[2025-03-24 12:21:06,441][flwr][INFO] - Round 6: selected clients
            ['4', '3', '5', '7', '9', '6', '8', '1', '2'] for fit.
[2025-03-24 12:21:06,441][flwr][DEBUG] - fit_round 6: strategy sampled 9 clients (out of 10)
[2025-03-24 12:21:24,510][flwr][DEBUG] - fit_round 6 received 9 results and 0 failures
[2025-03-24 12:21:25,571][flwr][INFO] - fit progress: (6, 2.543081760406494, {'accuracy': 0.22020000219345093}, 150.50534249999328)
[2025-03-24 12:21:25,571][flwr][DEBUG] - evaluate_round 6: strategy sampled 9 clients (out of 10)
[2025-03-24 12:21:27,658][flwr][DEBUG] - evaluate_round 6 received 9 results and 0 failures
[2025-03-24 12:21:30,471][flwr][INFO] - Server 7: selected clients
                ['2', '5', '3', '4', '6', '7', '1', '0', '8', '9'] for first phase evaluation.
[2025-03-24 12:21:30,471][flwr][DEBUG] - evaluate_first_phase 7: strategy sampled 10 clients (out of 10)
[2025-03-24 12:21:30,755][flwr][ERROR] - Traceback (most recent call last):
  File "/opt/anaconda3/envs/NodeSelection/lib/python3.10/site-packages/flwr/simulation/ray_transport/ray_client_proxy.py", line 140, in _submit_job
    res = self.actor_pool.get_client_result(self.cid, timeout)
  File "/opt/anaconda3/envs/NodeSelection/lib/python3.10/site-packages/flwr/simulation/ray_transport/ray_actor.py", line 402, in get_client_result
    return self._fetch_future_result(cid)
  File "/opt/anaconda3/envs/NodeSelection/lib/python3.10/site-packages/flwr/simulation/ray_transport/ray_actor.py", line 288, in _fetch_future_result
    res_cid, res = ray.get(future)  # type: (str, ClientRes)
  File "/opt/anaconda3/envs/NodeSelection/lib/python3.10/site-packages/ray/_private/auto_init_hook.py", line 21, in auto_init_wrapper
    return fn(*args, **kwargs)
  File "/opt/anaconda3/envs/NodeSelection/lib/python3.10/site-packages/ray/_private/client_mode_hook.py", line 103, in wrapper
    return func(*args, **kwargs)
  File "/opt/anaconda3/envs/NodeSelection/lib/python3.10/site-packages/ray/_private/worker.py", line 2771, in get
    values, debugger_breakpoint = worker.get_objects(object_refs, timeout=timeout)
  File "/opt/anaconda3/envs/NodeSelection/lib/python3.10/site-packages/ray/_private/worker.py", line 919, in get_objects
    raise value.as_instanceof_cause()
ray.exceptions.RayTaskError(ClientException): [36mray::DefaultActor.run()[39m (pid=15293, ip=127.0.0.1, actor_id=117b0f97ac94b062612ccb7d01000000, repr=<flwr.simulation.ray_transport.ray_actor.DefaultActor object at 0x1655b4bb0>)
  File "/opt/anaconda3/envs/NodeSelection/lib/python3.10/site-packages/flwr/simulation/ray_transport/ray_client_proxy.py", line 215, in evaluate
    return maybe_call_evaluate(
  File "/opt/anaconda3/envs/NodeSelection/lib/python3.10/site-packages/flwr/client/client.py", line 237, in maybe_call_evaluate
    return client.evaluate(evaluate_ins)
  File "/opt/anaconda3/envs/NodeSelection/lib/python3.10/site-packages/flwr/client/app.py", line 357, in _evaluate
    results = self.numpy_client.evaluate(parameters, ins.config)  # type: ignore
  File "/Users/livialestingi/PycharmProjects/NodeSelection/power_of_choice/power_of_choice/client_ecto.py", line 90, in evaluate
    idx = np.random.choice(len(x_entire), b, replace=False)
  File "mtrand.pyx", line 984, in numpy.random.mtrand.RandomState.choice
ValueError: Cannot take a larger sample than population when 'replace=False'

The above exception was the direct cause of the following exception:

[36mray::DefaultActor.run()[39m (pid=15293, ip=127.0.0.1, actor_id=117b0f97ac94b062612ccb7d01000000, repr=<flwr.simulation.ray_transport.ray_actor.DefaultActor object at 0x1655b4bb0>)
  File "/opt/anaconda3/envs/NodeSelection/lib/python3.10/site-packages/flwr/simulation/ray_transport/ray_actor.py", line 72, in run
    raise ClientException(str(message)) from ex
flwr.simulation.ray_transport.ray_actor.ClientException: 
>>>>>>>A ClientException occurred.('\n\tSomething went wrong when running your client workload.\n\tClient 0 crashed when the DefaultActor was running its workload.\n\tException triggered on the client side: Traceback (most recent call last):\n  File "/opt/anaconda3/envs/NodeSelection/lib/python3.10/site-packages/flwr/simulation/ray_transport/ray_actor.py", line 60, in run\n    job_results = job_fn()\n  File "/opt/anaconda3/envs/NodeSelection/lib/python3.10/site-packages/flwr/simulation/ray_transport/ray_client_proxy.py", line 215, in evaluate\n    return maybe_call_evaluate(\n  File "/opt/anaconda3/envs/NodeSelection/lib/python3.10/site-packages/flwr/client/client.py", line 237, in maybe_call_evaluate\n    return client.evaluate(evaluate_ins)\n  File "/opt/anaconda3/envs/NodeSelection/lib/python3.10/site-packages/flwr/client/app.py", line 357, in _evaluate\n    results = self.numpy_client.evaluate(parameters, ins.config)  # type: ignore\n  File "/Users/livialestingi/PycharmProjects/NodeSelection/power_of_choice/power_of_choice/client_ecto.py", line 90, in evaluate\n    idx = np.random.choice(len(x_entire), b, replace=False)\n  File "mtrand.pyx", line 984, in numpy.random.mtrand.RandomState.choice\nValueError: Cannot take a larger sample than population when \'replace=False\'\n',)

[2025-03-24 12:21:30,758][flwr][ERROR] - [36mray::DefaultActor.run()[39m (pid=15293, ip=127.0.0.1, actor_id=117b0f97ac94b062612ccb7d01000000, repr=<flwr.simulation.ray_transport.ray_actor.DefaultActor object at 0x1655b4bb0>)
  File "/opt/anaconda3/envs/NodeSelection/lib/python3.10/site-packages/flwr/simulation/ray_transport/ray_client_proxy.py", line 215, in evaluate
    return maybe_call_evaluate(
  File "/opt/anaconda3/envs/NodeSelection/lib/python3.10/site-packages/flwr/client/client.py", line 237, in maybe_call_evaluate
    return client.evaluate(evaluate_ins)
  File "/opt/anaconda3/envs/NodeSelection/lib/python3.10/site-packages/flwr/client/app.py", line 357, in _evaluate
    results = self.numpy_client.evaluate(parameters, ins.config)  # type: ignore
  File "/Users/livialestingi/PycharmProjects/NodeSelection/power_of_choice/power_of_choice/client_ecto.py", line 90, in evaluate
    idx = np.random.choice(len(x_entire), b, replace=False)
  File "mtrand.pyx", line 984, in numpy.random.mtrand.RandomState.choice
ValueError: Cannot take a larger sample than population when 'replace=False'

The above exception was the direct cause of the following exception:

[36mray::DefaultActor.run()[39m (pid=15293, ip=127.0.0.1, actor_id=117b0f97ac94b062612ccb7d01000000, repr=<flwr.simulation.ray_transport.ray_actor.DefaultActor object at 0x1655b4bb0>)
  File "/opt/anaconda3/envs/NodeSelection/lib/python3.10/site-packages/flwr/simulation/ray_transport/ray_actor.py", line 72, in run
    raise ClientException(str(message)) from ex
flwr.simulation.ray_transport.ray_actor.ClientException: 
>>>>>>>A ClientException occurred.('\n\tSomething went wrong when running your client workload.\n\tClient 0 crashed when the DefaultActor was running its workload.\n\tException triggered on the client side: Traceback (most recent call last):\n  File "/opt/anaconda3/envs/NodeSelection/lib/python3.10/site-packages/flwr/simulation/ray_transport/ray_actor.py", line 60, in run\n    job_results = job_fn()\n  File "/opt/anaconda3/envs/NodeSelection/lib/python3.10/site-packages/flwr/simulation/ray_transport/ray_client_proxy.py", line 215, in evaluate\n    return maybe_call_evaluate(\n  File "/opt/anaconda3/envs/NodeSelection/lib/python3.10/site-packages/flwr/client/client.py", line 237, in maybe_call_evaluate\n    return client.evaluate(evaluate_ins)\n  File "/opt/anaconda3/envs/NodeSelection/lib/python3.10/site-packages/flwr/client/app.py", line 357, in _evaluate\n    results = self.numpy_client.evaluate(parameters, ins.config)  # type: ignore\n  File "/Users/livialestingi/PycharmProjects/NodeSelection/power_of_choice/power_of_choice/client_ecto.py", line 90, in evaluate\n    idx = np.random.choice(len(x_entire), b, replace=False)\n  File "mtrand.pyx", line 984, in numpy.random.mtrand.RandomState.choice\nValueError: Cannot take a larger sample than population when \'replace=False\'\n',)
[2025-03-24 12:21:32,409][flwr][DEBUG] - evaluate_first_phase of round 7 received 9 results and 1 failures
[2025-03-24 12:21:32,409][flwr][INFO] - Server 7: about to sample 9 clients
[2025-03-24 12:21:32,409][flwr][INFO] - Round 7: selected clients
            ['7', '9', '5', '4', '3', '2', '6', '8', '1'] for fit.
[2025-03-24 12:21:32,409][flwr][DEBUG] - fit_round 7: strategy sampled 9 clients (out of 10)
[2025-03-24 12:21:50,619][flwr][DEBUG] - fit_round 7 received 9 results and 0 failures
[2025-03-24 12:21:51,671][flwr][INFO] - fit progress: (7, 1.535627007484436, {'accuracy': 0.42250001430511475}, 176.605032499996)
[2025-03-24 12:21:51,671][flwr][DEBUG] - evaluate_round 7: strategy sampled 9 clients (out of 10)
[2025-03-24 12:21:53,740][flwr][DEBUG] - evaluate_round 7 received 9 results and 0 failures
[2025-03-24 12:21:56,521][flwr][INFO] - Server 8: selected clients
                ['4', '8', '2', '0', '9', '7', '3', '6', '1', '5'] for first phase evaluation.
[2025-03-24 12:21:56,521][flwr][DEBUG] - evaluate_first_phase 8: strategy sampled 10 clients (out of 10)
[2025-03-24 12:21:56,678][flwr][ERROR] - Traceback (most recent call last):
  File "/opt/anaconda3/envs/NodeSelection/lib/python3.10/site-packages/flwr/simulation/ray_transport/ray_client_proxy.py", line 140, in _submit_job
    res = self.actor_pool.get_client_result(self.cid, timeout)
  File "/opt/anaconda3/envs/NodeSelection/lib/python3.10/site-packages/flwr/simulation/ray_transport/ray_actor.py", line 402, in get_client_result
    return self._fetch_future_result(cid)
  File "/opt/anaconda3/envs/NodeSelection/lib/python3.10/site-packages/flwr/simulation/ray_transport/ray_actor.py", line 288, in _fetch_future_result
    res_cid, res = ray.get(future)  # type: (str, ClientRes)
  File "/opt/anaconda3/envs/NodeSelection/lib/python3.10/site-packages/ray/_private/auto_init_hook.py", line 21, in auto_init_wrapper
    return fn(*args, **kwargs)
  File "/opt/anaconda3/envs/NodeSelection/lib/python3.10/site-packages/ray/_private/client_mode_hook.py", line 103, in wrapper
    return func(*args, **kwargs)
  File "/opt/anaconda3/envs/NodeSelection/lib/python3.10/site-packages/ray/_private/worker.py", line 2771, in get
    values, debugger_breakpoint = worker.get_objects(object_refs, timeout=timeout)
  File "/opt/anaconda3/envs/NodeSelection/lib/python3.10/site-packages/ray/_private/worker.py", line 919, in get_objects
    raise value.as_instanceof_cause()
ray.exceptions.RayTaskError(ClientException): [36mray::DefaultActor.run()[39m (pid=15288, ip=127.0.0.1, actor_id=ddad64d674d78daa40630f4d01000000, repr=<flwr.simulation.ray_transport.ray_actor.DefaultActor object at 0x160f7cb50>)
  File "/opt/anaconda3/envs/NodeSelection/lib/python3.10/site-packages/flwr/simulation/ray_transport/ray_client_proxy.py", line 215, in evaluate
    return maybe_call_evaluate(
  File "/opt/anaconda3/envs/NodeSelection/lib/python3.10/site-packages/flwr/client/client.py", line 237, in maybe_call_evaluate
    return client.evaluate(evaluate_ins)
  File "/opt/anaconda3/envs/NodeSelection/lib/python3.10/site-packages/flwr/client/app.py", line 357, in _evaluate
    results = self.numpy_client.evaluate(parameters, ins.config)  # type: ignore
  File "/Users/livialestingi/PycharmProjects/NodeSelection/power_of_choice/power_of_choice/client_ecto.py", line 90, in evaluate
    idx = np.random.choice(len(x_entire), b, replace=False)
  File "mtrand.pyx", line 984, in numpy.random.mtrand.RandomState.choice
ValueError: Cannot take a larger sample than population when 'replace=False'

The above exception was the direct cause of the following exception:

[36mray::DefaultActor.run()[39m (pid=15288, ip=127.0.0.1, actor_id=ddad64d674d78daa40630f4d01000000, repr=<flwr.simulation.ray_transport.ray_actor.DefaultActor object at 0x160f7cb50>)
  File "/opt/anaconda3/envs/NodeSelection/lib/python3.10/site-packages/flwr/simulation/ray_transport/ray_actor.py", line 72, in run
    raise ClientException(str(message)) from ex
flwr.simulation.ray_transport.ray_actor.ClientException: 
>>>>>>>A ClientException occurred.('\n\tSomething went wrong when running your client workload.\n\tClient 0 crashed when the DefaultActor was running its workload.\n\tException triggered on the client side: Traceback (most recent call last):\n  File "/opt/anaconda3/envs/NodeSelection/lib/python3.10/site-packages/flwr/simulation/ray_transport/ray_actor.py", line 60, in run\n    job_results = job_fn()\n  File "/opt/anaconda3/envs/NodeSelection/lib/python3.10/site-packages/flwr/simulation/ray_transport/ray_client_proxy.py", line 215, in evaluate\n    return maybe_call_evaluate(\n  File "/opt/anaconda3/envs/NodeSelection/lib/python3.10/site-packages/flwr/client/client.py", line 237, in maybe_call_evaluate\n    return client.evaluate(evaluate_ins)\n  File "/opt/anaconda3/envs/NodeSelection/lib/python3.10/site-packages/flwr/client/app.py", line 357, in _evaluate\n    results = self.numpy_client.evaluate(parameters, ins.config)  # type: ignore\n  File "/Users/livialestingi/PycharmProjects/NodeSelection/power_of_choice/power_of_choice/client_ecto.py", line 90, in evaluate\n    idx = np.random.choice(len(x_entire), b, replace=False)\n  File "mtrand.pyx", line 984, in numpy.random.mtrand.RandomState.choice\nValueError: Cannot take a larger sample than population when \'replace=False\'\n',)

[2025-03-24 12:21:56,680][flwr][ERROR] - [36mray::DefaultActor.run()[39m (pid=15288, ip=127.0.0.1, actor_id=ddad64d674d78daa40630f4d01000000, repr=<flwr.simulation.ray_transport.ray_actor.DefaultActor object at 0x160f7cb50>)
  File "/opt/anaconda3/envs/NodeSelection/lib/python3.10/site-packages/flwr/simulation/ray_transport/ray_client_proxy.py", line 215, in evaluate
    return maybe_call_evaluate(
  File "/opt/anaconda3/envs/NodeSelection/lib/python3.10/site-packages/flwr/client/client.py", line 237, in maybe_call_evaluate
    return client.evaluate(evaluate_ins)
  File "/opt/anaconda3/envs/NodeSelection/lib/python3.10/site-packages/flwr/client/app.py", line 357, in _evaluate
    results = self.numpy_client.evaluate(parameters, ins.config)  # type: ignore
  File "/Users/livialestingi/PycharmProjects/NodeSelection/power_of_choice/power_of_choice/client_ecto.py", line 90, in evaluate
    idx = np.random.choice(len(x_entire), b, replace=False)
  File "mtrand.pyx", line 984, in numpy.random.mtrand.RandomState.choice
ValueError: Cannot take a larger sample than population when 'replace=False'

The above exception was the direct cause of the following exception:

[36mray::DefaultActor.run()[39m (pid=15288, ip=127.0.0.1, actor_id=ddad64d674d78daa40630f4d01000000, repr=<flwr.simulation.ray_transport.ray_actor.DefaultActor object at 0x160f7cb50>)
  File "/opt/anaconda3/envs/NodeSelection/lib/python3.10/site-packages/flwr/simulation/ray_transport/ray_actor.py", line 72, in run
    raise ClientException(str(message)) from ex
flwr.simulation.ray_transport.ray_actor.ClientException: 
>>>>>>>A ClientException occurred.('\n\tSomething went wrong when running your client workload.\n\tClient 0 crashed when the DefaultActor was running its workload.\n\tException triggered on the client side: Traceback (most recent call last):\n  File "/opt/anaconda3/envs/NodeSelection/lib/python3.10/site-packages/flwr/simulation/ray_transport/ray_actor.py", line 60, in run\n    job_results = job_fn()\n  File "/opt/anaconda3/envs/NodeSelection/lib/python3.10/site-packages/flwr/simulation/ray_transport/ray_client_proxy.py", line 215, in evaluate\n    return maybe_call_evaluate(\n  File "/opt/anaconda3/envs/NodeSelection/lib/python3.10/site-packages/flwr/client/client.py", line 237, in maybe_call_evaluate\n    return client.evaluate(evaluate_ins)\n  File "/opt/anaconda3/envs/NodeSelection/lib/python3.10/site-packages/flwr/client/app.py", line 357, in _evaluate\n    results = self.numpy_client.evaluate(parameters, ins.config)  # type: ignore\n  File "/Users/livialestingi/PycharmProjects/NodeSelection/power_of_choice/power_of_choice/client_ecto.py", line 90, in evaluate\n    idx = np.random.choice(len(x_entire), b, replace=False)\n  File "mtrand.pyx", line 984, in numpy.random.mtrand.RandomState.choice\nValueError: Cannot take a larger sample than population when \'replace=False\'\n',)
[2025-03-24 12:21:58,486][flwr][DEBUG] - evaluate_first_phase of round 8 received 9 results and 1 failures
[2025-03-24 12:21:58,487][flwr][INFO] - Server 8: about to sample 9 clients
[2025-03-24 12:21:58,487][flwr][INFO] - Round 8: selected clients
            ['3', '8', '2', '1', '9', '4', '5', '7', '6'] for fit.
[2025-03-24 12:21:58,487][flwr][DEBUG] - fit_round 8: strategy sampled 9 clients (out of 10)
[2025-03-24 12:22:16,342][flwr][DEBUG] - fit_round 8 received 9 results and 0 failures
[2025-03-24 12:22:17,363][flwr][INFO] - fit progress: (8, 1.4188491106033325, {'accuracy': 0.487199991941452}, 202.29695362499479)
[2025-03-24 12:22:17,363][flwr][DEBUG] - evaluate_round 8: strategy sampled 9 clients (out of 10)
[2025-03-24 12:22:19,417][flwr][DEBUG] - evaluate_round 8 received 9 results and 0 failures
[2025-03-24 12:22:22,224][flwr][INFO] - Server 9: selected clients
                ['7', '9', '3', '1', '4', '0', '6', '5', '8', '2'] for first phase evaluation.
[2025-03-24 12:22:22,225][flwr][DEBUG] - evaluate_first_phase 9: strategy sampled 10 clients (out of 10)
[2025-03-24 12:22:22,466][flwr][ERROR] - Traceback (most recent call last):
  File "/opt/anaconda3/envs/NodeSelection/lib/python3.10/site-packages/flwr/simulation/ray_transport/ray_client_proxy.py", line 140, in _submit_job
    res = self.actor_pool.get_client_result(self.cid, timeout)
  File "/opt/anaconda3/envs/NodeSelection/lib/python3.10/site-packages/flwr/simulation/ray_transport/ray_actor.py", line 402, in get_client_result
    return self._fetch_future_result(cid)
  File "/opt/anaconda3/envs/NodeSelection/lib/python3.10/site-packages/flwr/simulation/ray_transport/ray_actor.py", line 288, in _fetch_future_result
    res_cid, res = ray.get(future)  # type: (str, ClientRes)
  File "/opt/anaconda3/envs/NodeSelection/lib/python3.10/site-packages/ray/_private/auto_init_hook.py", line 21, in auto_init_wrapper
    return fn(*args, **kwargs)
  File "/opt/anaconda3/envs/NodeSelection/lib/python3.10/site-packages/ray/_private/client_mode_hook.py", line 103, in wrapper
    return func(*args, **kwargs)
  File "/opt/anaconda3/envs/NodeSelection/lib/python3.10/site-packages/ray/_private/worker.py", line 2771, in get
    values, debugger_breakpoint = worker.get_objects(object_refs, timeout=timeout)
  File "/opt/anaconda3/envs/NodeSelection/lib/python3.10/site-packages/ray/_private/worker.py", line 919, in get_objects
    raise value.as_instanceof_cause()
ray.exceptions.RayTaskError(ClientException): [36mray::DefaultActor.run()[39m (pid=15294, ip=127.0.0.1, actor_id=e0912b4a13da5450036192dc01000000, repr=<flwr.simulation.ray_transport.ray_actor.DefaultActor object at 0x1519a8b20>)
  File "/opt/anaconda3/envs/NodeSelection/lib/python3.10/site-packages/flwr/simulation/ray_transport/ray_client_proxy.py", line 215, in evaluate
    return maybe_call_evaluate(
  File "/opt/anaconda3/envs/NodeSelection/lib/python3.10/site-packages/flwr/client/client.py", line 237, in maybe_call_evaluate
    return client.evaluate(evaluate_ins)
  File "/opt/anaconda3/envs/NodeSelection/lib/python3.10/site-packages/flwr/client/app.py", line 357, in _evaluate
    results = self.numpy_client.evaluate(parameters, ins.config)  # type: ignore
  File "/Users/livialestingi/PycharmProjects/NodeSelection/power_of_choice/power_of_choice/client_ecto.py", line 90, in evaluate
    idx = np.random.choice(len(x_entire), b, replace=False)
  File "mtrand.pyx", line 984, in numpy.random.mtrand.RandomState.choice
ValueError: Cannot take a larger sample than population when 'replace=False'

The above exception was the direct cause of the following exception:

[36mray::DefaultActor.run()[39m (pid=15294, ip=127.0.0.1, actor_id=e0912b4a13da5450036192dc01000000, repr=<flwr.simulation.ray_transport.ray_actor.DefaultActor object at 0x1519a8b20>)
  File "/opt/anaconda3/envs/NodeSelection/lib/python3.10/site-packages/flwr/simulation/ray_transport/ray_actor.py", line 72, in run
    raise ClientException(str(message)) from ex
flwr.simulation.ray_transport.ray_actor.ClientException: 
>>>>>>>A ClientException occurred.('\n\tSomething went wrong when running your client workload.\n\tClient 0 crashed when the DefaultActor was running its workload.\n\tException triggered on the client side: Traceback (most recent call last):\n  File "/opt/anaconda3/envs/NodeSelection/lib/python3.10/site-packages/flwr/simulation/ray_transport/ray_actor.py", line 60, in run\n    job_results = job_fn()\n  File "/opt/anaconda3/envs/NodeSelection/lib/python3.10/site-packages/flwr/simulation/ray_transport/ray_client_proxy.py", line 215, in evaluate\n    return maybe_call_evaluate(\n  File "/opt/anaconda3/envs/NodeSelection/lib/python3.10/site-packages/flwr/client/client.py", line 237, in maybe_call_evaluate\n    return client.evaluate(evaluate_ins)\n  File "/opt/anaconda3/envs/NodeSelection/lib/python3.10/site-packages/flwr/client/app.py", line 357, in _evaluate\n    results = self.numpy_client.evaluate(parameters, ins.config)  # type: ignore\n  File "/Users/livialestingi/PycharmProjects/NodeSelection/power_of_choice/power_of_choice/client_ecto.py", line 90, in evaluate\n    idx = np.random.choice(len(x_entire), b, replace=False)\n  File "mtrand.pyx", line 984, in numpy.random.mtrand.RandomState.choice\nValueError: Cannot take a larger sample than population when \'replace=False\'\n',)

[2025-03-24 12:22:22,470][flwr][ERROR] - [36mray::DefaultActor.run()[39m (pid=15294, ip=127.0.0.1, actor_id=e0912b4a13da5450036192dc01000000, repr=<flwr.simulation.ray_transport.ray_actor.DefaultActor object at 0x1519a8b20>)
  File "/opt/anaconda3/envs/NodeSelection/lib/python3.10/site-packages/flwr/simulation/ray_transport/ray_client_proxy.py", line 215, in evaluate
    return maybe_call_evaluate(
  File "/opt/anaconda3/envs/NodeSelection/lib/python3.10/site-packages/flwr/client/client.py", line 237, in maybe_call_evaluate
    return client.evaluate(evaluate_ins)
  File "/opt/anaconda3/envs/NodeSelection/lib/python3.10/site-packages/flwr/client/app.py", line 357, in _evaluate
    results = self.numpy_client.evaluate(parameters, ins.config)  # type: ignore
  File "/Users/livialestingi/PycharmProjects/NodeSelection/power_of_choice/power_of_choice/client_ecto.py", line 90, in evaluate
    idx = np.random.choice(len(x_entire), b, replace=False)
  File "mtrand.pyx", line 984, in numpy.random.mtrand.RandomState.choice
ValueError: Cannot take a larger sample than population when 'replace=False'

The above exception was the direct cause of the following exception:

[36mray::DefaultActor.run()[39m (pid=15294, ip=127.0.0.1, actor_id=e0912b4a13da5450036192dc01000000, repr=<flwr.simulation.ray_transport.ray_actor.DefaultActor object at 0x1519a8b20>)
  File "/opt/anaconda3/envs/NodeSelection/lib/python3.10/site-packages/flwr/simulation/ray_transport/ray_actor.py", line 72, in run
    raise ClientException(str(message)) from ex
flwr.simulation.ray_transport.ray_actor.ClientException: 
>>>>>>>A ClientException occurred.('\n\tSomething went wrong when running your client workload.\n\tClient 0 crashed when the DefaultActor was running its workload.\n\tException triggered on the client side: Traceback (most recent call last):\n  File "/opt/anaconda3/envs/NodeSelection/lib/python3.10/site-packages/flwr/simulation/ray_transport/ray_actor.py", line 60, in run\n    job_results = job_fn()\n  File "/opt/anaconda3/envs/NodeSelection/lib/python3.10/site-packages/flwr/simulation/ray_transport/ray_client_proxy.py", line 215, in evaluate\n    return maybe_call_evaluate(\n  File "/opt/anaconda3/envs/NodeSelection/lib/python3.10/site-packages/flwr/client/client.py", line 237, in maybe_call_evaluate\n    return client.evaluate(evaluate_ins)\n  File "/opt/anaconda3/envs/NodeSelection/lib/python3.10/site-packages/flwr/client/app.py", line 357, in _evaluate\n    results = self.numpy_client.evaluate(parameters, ins.config)  # type: ignore\n  File "/Users/livialestingi/PycharmProjects/NodeSelection/power_of_choice/power_of_choice/client_ecto.py", line 90, in evaluate\n    idx = np.random.choice(len(x_entire), b, replace=False)\n  File "mtrand.pyx", line 984, in numpy.random.mtrand.RandomState.choice\nValueError: Cannot take a larger sample than population when \'replace=False\'\n',)
[2025-03-24 12:22:24,158][flwr][DEBUG] - evaluate_first_phase of round 9 received 9 results and 1 failures
[2025-03-24 12:22:24,158][flwr][INFO] - Server 9: about to sample 9 clients
[2025-03-24 12:22:24,158][flwr][INFO] - Round 9: selected clients
            ['5', '2', '7', '6', '1', '8', '9', '3', '4'] for fit.
[2025-03-24 12:22:24,159][flwr][DEBUG] - fit_round 9: strategy sampled 9 clients (out of 10)
[2025-03-24 12:22:42,106][flwr][DEBUG] - fit_round 9 received 9 results and 0 failures
[2025-03-24 12:22:43,149][flwr][INFO] - fit progress: (9, 1.5399237871170044, {'accuracy': 0.43810001015663147}, 228.08350970799802)
[2025-03-24 12:22:43,149][flwr][DEBUG] - evaluate_round 9: strategy sampled 9 clients (out of 10)
[2025-03-24 12:22:45,354][flwr][DEBUG] - evaluate_round 9 received 9 results and 0 failures
[2025-03-24 12:22:48,148][flwr][INFO] - Server 10: selected clients
                ['4', '5', '1', '0', '9', '8', '6', '3', '7', '2'] for first phase evaluation.
[2025-03-24 12:22:48,148][flwr][DEBUG] - evaluate_first_phase 10: strategy sampled 10 clients (out of 10)
[2025-03-24 12:22:48,294][flwr][ERROR] - Traceback (most recent call last):
  File "/opt/anaconda3/envs/NodeSelection/lib/python3.10/site-packages/flwr/simulation/ray_transport/ray_client_proxy.py", line 140, in _submit_job
    res = self.actor_pool.get_client_result(self.cid, timeout)
  File "/opt/anaconda3/envs/NodeSelection/lib/python3.10/site-packages/flwr/simulation/ray_transport/ray_actor.py", line 402, in get_client_result
    return self._fetch_future_result(cid)
  File "/opt/anaconda3/envs/NodeSelection/lib/python3.10/site-packages/flwr/simulation/ray_transport/ray_actor.py", line 288, in _fetch_future_result
    res_cid, res = ray.get(future)  # type: (str, ClientRes)
  File "/opt/anaconda3/envs/NodeSelection/lib/python3.10/site-packages/ray/_private/auto_init_hook.py", line 21, in auto_init_wrapper
    return fn(*args, **kwargs)
  File "/opt/anaconda3/envs/NodeSelection/lib/python3.10/site-packages/ray/_private/client_mode_hook.py", line 103, in wrapper
    return func(*args, **kwargs)
  File "/opt/anaconda3/envs/NodeSelection/lib/python3.10/site-packages/ray/_private/worker.py", line 2771, in get
    values, debugger_breakpoint = worker.get_objects(object_refs, timeout=timeout)
  File "/opt/anaconda3/envs/NodeSelection/lib/python3.10/site-packages/ray/_private/worker.py", line 919, in get_objects
    raise value.as_instanceof_cause()
ray.exceptions.RayTaskError(ClientException): [36mray::DefaultActor.run()[39m (pid=15289, ip=127.0.0.1, actor_id=6e88e79ef1ee7334ee7f72e501000000, repr=<flwr.simulation.ray_transport.ray_actor.DefaultActor object at 0x14a780b50>)
  File "/opt/anaconda3/envs/NodeSelection/lib/python3.10/site-packages/flwr/simulation/ray_transport/ray_client_proxy.py", line 215, in evaluate
    return maybe_call_evaluate(
  File "/opt/anaconda3/envs/NodeSelection/lib/python3.10/site-packages/flwr/client/client.py", line 237, in maybe_call_evaluate
    return client.evaluate(evaluate_ins)
  File "/opt/anaconda3/envs/NodeSelection/lib/python3.10/site-packages/flwr/client/app.py", line 357, in _evaluate
    results = self.numpy_client.evaluate(parameters, ins.config)  # type: ignore
  File "/Users/livialestingi/PycharmProjects/NodeSelection/power_of_choice/power_of_choice/client_ecto.py", line 90, in evaluate
    idx = np.random.choice(len(x_entire), b, replace=False)
  File "mtrand.pyx", line 984, in numpy.random.mtrand.RandomState.choice
ValueError: Cannot take a larger sample than population when 'replace=False'

The above exception was the direct cause of the following exception:

[36mray::DefaultActor.run()[39m (pid=15289, ip=127.0.0.1, actor_id=6e88e79ef1ee7334ee7f72e501000000, repr=<flwr.simulation.ray_transport.ray_actor.DefaultActor object at 0x14a780b50>)
  File "/opt/anaconda3/envs/NodeSelection/lib/python3.10/site-packages/flwr/simulation/ray_transport/ray_actor.py", line 72, in run
    raise ClientException(str(message)) from ex
flwr.simulation.ray_transport.ray_actor.ClientException: 
>>>>>>>A ClientException occurred.('\n\tSomething went wrong when running your client workload.\n\tClient 0 crashed when the DefaultActor was running its workload.\n\tException triggered on the client side: Traceback (most recent call last):\n  File "/opt/anaconda3/envs/NodeSelection/lib/python3.10/site-packages/flwr/simulation/ray_transport/ray_actor.py", line 60, in run\n    job_results = job_fn()\n  File "/opt/anaconda3/envs/NodeSelection/lib/python3.10/site-packages/flwr/simulation/ray_transport/ray_client_proxy.py", line 215, in evaluate\n    return maybe_call_evaluate(\n  File "/opt/anaconda3/envs/NodeSelection/lib/python3.10/site-packages/flwr/client/client.py", line 237, in maybe_call_evaluate\n    return client.evaluate(evaluate_ins)\n  File "/opt/anaconda3/envs/NodeSelection/lib/python3.10/site-packages/flwr/client/app.py", line 357, in _evaluate\n    results = self.numpy_client.evaluate(parameters, ins.config)  # type: ignore\n  File "/Users/livialestingi/PycharmProjects/NodeSelection/power_of_choice/power_of_choice/client_ecto.py", line 90, in evaluate\n    idx = np.random.choice(len(x_entire), b, replace=False)\n  File "mtrand.pyx", line 984, in numpy.random.mtrand.RandomState.choice\nValueError: Cannot take a larger sample than population when \'replace=False\'\n',)

[2025-03-24 12:22:48,296][flwr][ERROR] - [36mray::DefaultActor.run()[39m (pid=15289, ip=127.0.0.1, actor_id=6e88e79ef1ee7334ee7f72e501000000, repr=<flwr.simulation.ray_transport.ray_actor.DefaultActor object at 0x14a780b50>)
  File "/opt/anaconda3/envs/NodeSelection/lib/python3.10/site-packages/flwr/simulation/ray_transport/ray_client_proxy.py", line 215, in evaluate
    return maybe_call_evaluate(
  File "/opt/anaconda3/envs/NodeSelection/lib/python3.10/site-packages/flwr/client/client.py", line 237, in maybe_call_evaluate
    return client.evaluate(evaluate_ins)
  File "/opt/anaconda3/envs/NodeSelection/lib/python3.10/site-packages/flwr/client/app.py", line 357, in _evaluate
    results = self.numpy_client.evaluate(parameters, ins.config)  # type: ignore
  File "/Users/livialestingi/PycharmProjects/NodeSelection/power_of_choice/power_of_choice/client_ecto.py", line 90, in evaluate
    idx = np.random.choice(len(x_entire), b, replace=False)
  File "mtrand.pyx", line 984, in numpy.random.mtrand.RandomState.choice
ValueError: Cannot take a larger sample than population when 'replace=False'

The above exception was the direct cause of the following exception:

[36mray::DefaultActor.run()[39m (pid=15289, ip=127.0.0.1, actor_id=6e88e79ef1ee7334ee7f72e501000000, repr=<flwr.simulation.ray_transport.ray_actor.DefaultActor object at 0x14a780b50>)
  File "/opt/anaconda3/envs/NodeSelection/lib/python3.10/site-packages/flwr/simulation/ray_transport/ray_actor.py", line 72, in run
    raise ClientException(str(message)) from ex
flwr.simulation.ray_transport.ray_actor.ClientException: 
>>>>>>>A ClientException occurred.('\n\tSomething went wrong when running your client workload.\n\tClient 0 crashed when the DefaultActor was running its workload.\n\tException triggered on the client side: Traceback (most recent call last):\n  File "/opt/anaconda3/envs/NodeSelection/lib/python3.10/site-packages/flwr/simulation/ray_transport/ray_actor.py", line 60, in run\n    job_results = job_fn()\n  File "/opt/anaconda3/envs/NodeSelection/lib/python3.10/site-packages/flwr/simulation/ray_transport/ray_client_proxy.py", line 215, in evaluate\n    return maybe_call_evaluate(\n  File "/opt/anaconda3/envs/NodeSelection/lib/python3.10/site-packages/flwr/client/client.py", line 237, in maybe_call_evaluate\n    return client.evaluate(evaluate_ins)\n  File "/opt/anaconda3/envs/NodeSelection/lib/python3.10/site-packages/flwr/client/app.py", line 357, in _evaluate\n    results = self.numpy_client.evaluate(parameters, ins.config)  # type: ignore\n  File "/Users/livialestingi/PycharmProjects/NodeSelection/power_of_choice/power_of_choice/client_ecto.py", line 90, in evaluate\n    idx = np.random.choice(len(x_entire), b, replace=False)\n  File "mtrand.pyx", line 984, in numpy.random.mtrand.RandomState.choice\nValueError: Cannot take a larger sample than population when \'replace=False\'\n',)
[2025-03-24 12:22:50,257][flwr][DEBUG] - evaluate_first_phase of round 10 received 9 results and 1 failures
[2025-03-24 12:22:50,257][flwr][INFO] - Server 10: about to sample 9 clients
[2025-03-24 12:22:50,257][flwr][INFO] - Round 10: selected clients
            ['4', '6', '7', '3', '2', '5', '1', '8', '9'] for fit.
[2025-03-24 12:22:50,257][flwr][DEBUG] - fit_round 10: strategy sampled 9 clients (out of 10)
[2025-03-24 12:23:07,799][flwr][DEBUG] - fit_round 10 received 9 results and 0 failures
[2025-03-24 12:23:08,905][flwr][INFO] - fit progress: (10, 1.622155785560608, {'accuracy': 0.41530001163482666}, 253.83951429099398)
[2025-03-24 12:23:08,905][flwr][DEBUG] - evaluate_round 10: strategy sampled 9 clients (out of 10)
[2025-03-24 12:23:11,084][flwr][DEBUG] - evaluate_round 10 received 9 results and 0 failures
[2025-03-24 12:23:13,912][flwr][INFO] - Server 11: selected clients
                ['6', '7', '1', '8', '0', '3', '9', '4', '5', '2'] for first phase evaluation.
[2025-03-24 12:23:13,912][flwr][DEBUG] - evaluate_first_phase 11: strategy sampled 10 clients (out of 10)
[2025-03-24 12:23:14,127][flwr][ERROR] - Traceback (most recent call last):
  File "/opt/anaconda3/envs/NodeSelection/lib/python3.10/site-packages/flwr/simulation/ray_transport/ray_client_proxy.py", line 140, in _submit_job
    res = self.actor_pool.get_client_result(self.cid, timeout)
  File "/opt/anaconda3/envs/NodeSelection/lib/python3.10/site-packages/flwr/simulation/ray_transport/ray_actor.py", line 402, in get_client_result
    return self._fetch_future_result(cid)
  File "/opt/anaconda3/envs/NodeSelection/lib/python3.10/site-packages/flwr/simulation/ray_transport/ray_actor.py", line 288, in _fetch_future_result
    res_cid, res = ray.get(future)  # type: (str, ClientRes)
  File "/opt/anaconda3/envs/NodeSelection/lib/python3.10/site-packages/ray/_private/auto_init_hook.py", line 21, in auto_init_wrapper
    return fn(*args, **kwargs)
  File "/opt/anaconda3/envs/NodeSelection/lib/python3.10/site-packages/ray/_private/client_mode_hook.py", line 103, in wrapper
    return func(*args, **kwargs)
  File "/opt/anaconda3/envs/NodeSelection/lib/python3.10/site-packages/ray/_private/worker.py", line 2771, in get
    values, debugger_breakpoint = worker.get_objects(object_refs, timeout=timeout)
  File "/opt/anaconda3/envs/NodeSelection/lib/python3.10/site-packages/ray/_private/worker.py", line 919, in get_objects
    raise value.as_instanceof_cause()
ray.exceptions.RayTaskError(ClientException): [36mray::DefaultActor.run()[39m (pid=15284, ip=127.0.0.1, actor_id=948692ce9fb9c1e8140f598a01000000, repr=<flwr.simulation.ray_transport.ray_actor.DefaultActor object at 0x13a480a60>)
  File "/opt/anaconda3/envs/NodeSelection/lib/python3.10/site-packages/flwr/simulation/ray_transport/ray_client_proxy.py", line 215, in evaluate
    return maybe_call_evaluate(
  File "/opt/anaconda3/envs/NodeSelection/lib/python3.10/site-packages/flwr/client/client.py", line 237, in maybe_call_evaluate
    return client.evaluate(evaluate_ins)
  File "/opt/anaconda3/envs/NodeSelection/lib/python3.10/site-packages/flwr/client/app.py", line 357, in _evaluate
    results = self.numpy_client.evaluate(parameters, ins.config)  # type: ignore
  File "/Users/livialestingi/PycharmProjects/NodeSelection/power_of_choice/power_of_choice/client_ecto.py", line 90, in evaluate
    idx = np.random.choice(len(x_entire), b, replace=False)
  File "mtrand.pyx", line 984, in numpy.random.mtrand.RandomState.choice
ValueError: Cannot take a larger sample than population when 'replace=False'

The above exception was the direct cause of the following exception:

[36mray::DefaultActor.run()[39m (pid=15284, ip=127.0.0.1, actor_id=948692ce9fb9c1e8140f598a01000000, repr=<flwr.simulation.ray_transport.ray_actor.DefaultActor object at 0x13a480a60>)
  File "/opt/anaconda3/envs/NodeSelection/lib/python3.10/site-packages/flwr/simulation/ray_transport/ray_actor.py", line 72, in run
    raise ClientException(str(message)) from ex
flwr.simulation.ray_transport.ray_actor.ClientException: 
>>>>>>>A ClientException occurred.('\n\tSomething went wrong when running your client workload.\n\tClient 0 crashed when the DefaultActor was running its workload.\n\tException triggered on the client side: Traceback (most recent call last):\n  File "/opt/anaconda3/envs/NodeSelection/lib/python3.10/site-packages/flwr/simulation/ray_transport/ray_actor.py", line 60, in run\n    job_results = job_fn()\n  File "/opt/anaconda3/envs/NodeSelection/lib/python3.10/site-packages/flwr/simulation/ray_transport/ray_client_proxy.py", line 215, in evaluate\n    return maybe_call_evaluate(\n  File "/opt/anaconda3/envs/NodeSelection/lib/python3.10/site-packages/flwr/client/client.py", line 237, in maybe_call_evaluate\n    return client.evaluate(evaluate_ins)\n  File "/opt/anaconda3/envs/NodeSelection/lib/python3.10/site-packages/flwr/client/app.py", line 357, in _evaluate\n    results = self.numpy_client.evaluate(parameters, ins.config)  # type: ignore\n  File "/Users/livialestingi/PycharmProjects/NodeSelection/power_of_choice/power_of_choice/client_ecto.py", line 90, in evaluate\n    idx = np.random.choice(len(x_entire), b, replace=False)\n  File "mtrand.pyx", line 984, in numpy.random.mtrand.RandomState.choice\nValueError: Cannot take a larger sample than population when \'replace=False\'\n',)

[2025-03-24 12:23:14,130][flwr][ERROR] - [36mray::DefaultActor.run()[39m (pid=15284, ip=127.0.0.1, actor_id=948692ce9fb9c1e8140f598a01000000, repr=<flwr.simulation.ray_transport.ray_actor.DefaultActor object at 0x13a480a60>)
  File "/opt/anaconda3/envs/NodeSelection/lib/python3.10/site-packages/flwr/simulation/ray_transport/ray_client_proxy.py", line 215, in evaluate
    return maybe_call_evaluate(
  File "/opt/anaconda3/envs/NodeSelection/lib/python3.10/site-packages/flwr/client/client.py", line 237, in maybe_call_evaluate
    return client.evaluate(evaluate_ins)
  File "/opt/anaconda3/envs/NodeSelection/lib/python3.10/site-packages/flwr/client/app.py", line 357, in _evaluate
    results = self.numpy_client.evaluate(parameters, ins.config)  # type: ignore
  File "/Users/livialestingi/PycharmProjects/NodeSelection/power_of_choice/power_of_choice/client_ecto.py", line 90, in evaluate
    idx = np.random.choice(len(x_entire), b, replace=False)
  File "mtrand.pyx", line 984, in numpy.random.mtrand.RandomState.choice
ValueError: Cannot take a larger sample than population when 'replace=False'

The above exception was the direct cause of the following exception:

[36mray::DefaultActor.run()[39m (pid=15284, ip=127.0.0.1, actor_id=948692ce9fb9c1e8140f598a01000000, repr=<flwr.simulation.ray_transport.ray_actor.DefaultActor object at 0x13a480a60>)
  File "/opt/anaconda3/envs/NodeSelection/lib/python3.10/site-packages/flwr/simulation/ray_transport/ray_actor.py", line 72, in run
    raise ClientException(str(message)) from ex
flwr.simulation.ray_transport.ray_actor.ClientException: 
>>>>>>>A ClientException occurred.('\n\tSomething went wrong when running your client workload.\n\tClient 0 crashed when the DefaultActor was running its workload.\n\tException triggered on the client side: Traceback (most recent call last):\n  File "/opt/anaconda3/envs/NodeSelection/lib/python3.10/site-packages/flwr/simulation/ray_transport/ray_actor.py", line 60, in run\n    job_results = job_fn()\n  File "/opt/anaconda3/envs/NodeSelection/lib/python3.10/site-packages/flwr/simulation/ray_transport/ray_client_proxy.py", line 215, in evaluate\n    return maybe_call_evaluate(\n  File "/opt/anaconda3/envs/NodeSelection/lib/python3.10/site-packages/flwr/client/client.py", line 237, in maybe_call_evaluate\n    return client.evaluate(evaluate_ins)\n  File "/opt/anaconda3/envs/NodeSelection/lib/python3.10/site-packages/flwr/client/app.py", line 357, in _evaluate\n    results = self.numpy_client.evaluate(parameters, ins.config)  # type: ignore\n  File "/Users/livialestingi/PycharmProjects/NodeSelection/power_of_choice/power_of_choice/client_ecto.py", line 90, in evaluate\n    idx = np.random.choice(len(x_entire), b, replace=False)\n  File "mtrand.pyx", line 984, in numpy.random.mtrand.RandomState.choice\nValueError: Cannot take a larger sample than population when \'replace=False\'\n',)
[2025-03-24 12:23:15,969][flwr][DEBUG] - evaluate_first_phase of round 11 received 9 results and 1 failures
[2025-03-24 12:23:15,970][flwr][INFO] - Server 11: about to sample 9 clients
[2025-03-24 12:23:15,970][flwr][INFO] - Round 11: selected clients
            ['2', '1', '9', '8', '6', '4', '5', '3', '7'] for fit.
[2025-03-24 12:23:15,970][flwr][DEBUG] - fit_round 11: strategy sampled 9 clients (out of 10)
[2025-03-24 12:23:33,843][flwr][DEBUG] - fit_round 11 received 9 results and 0 failures
[2025-03-24 12:23:34,959][flwr][INFO] - fit progress: (11, 1.4801506996154785, {'accuracy': 0.45419999957084656}, 279.89306383299845)
[2025-03-24 12:23:34,959][flwr][DEBUG] - evaluate_round 11: strategy sampled 9 clients (out of 10)
[2025-03-24 12:23:37,215][flwr][DEBUG] - evaluate_round 11 received 9 results and 0 failures
[2025-03-24 12:23:40,055][flwr][INFO] - Server 12: selected clients
                ['2', '0', '6', '8', '9', '3', '7', '4', '5', '1'] for first phase evaluation.
[2025-03-24 12:23:40,055][flwr][DEBUG] - evaluate_first_phase 12: strategy sampled 10 clients (out of 10)
[2025-03-24 12:23:40,203][flwr][ERROR] - Traceback (most recent call last):
  File "/opt/anaconda3/envs/NodeSelection/lib/python3.10/site-packages/flwr/simulation/ray_transport/ray_client_proxy.py", line 140, in _submit_job
    res = self.actor_pool.get_client_result(self.cid, timeout)
  File "/opt/anaconda3/envs/NodeSelection/lib/python3.10/site-packages/flwr/simulation/ray_transport/ray_actor.py", line 402, in get_client_result
    return self._fetch_future_result(cid)
  File "/opt/anaconda3/envs/NodeSelection/lib/python3.10/site-packages/flwr/simulation/ray_transport/ray_actor.py", line 288, in _fetch_future_result
    res_cid, res = ray.get(future)  # type: (str, ClientRes)
  File "/opt/anaconda3/envs/NodeSelection/lib/python3.10/site-packages/ray/_private/auto_init_hook.py", line 21, in auto_init_wrapper
    return fn(*args, **kwargs)
  File "/opt/anaconda3/envs/NodeSelection/lib/python3.10/site-packages/ray/_private/client_mode_hook.py", line 103, in wrapper
    return func(*args, **kwargs)
  File "/opt/anaconda3/envs/NodeSelection/lib/python3.10/site-packages/ray/_private/worker.py", line 2771, in get
    values, debugger_breakpoint = worker.get_objects(object_refs, timeout=timeout)
  File "/opt/anaconda3/envs/NodeSelection/lib/python3.10/site-packages/ray/_private/worker.py", line 919, in get_objects
    raise value.as_instanceof_cause()
ray.exceptions.RayTaskError(ClientException): [36mray::DefaultActor.run()[39m (pid=15281, ip=127.0.0.1, actor_id=22a19f96bd8f8e9f9071114c01000000, repr=<flwr.simulation.ray_transport.ray_actor.DefaultActor object at 0x141180bb0>)
  File "/opt/anaconda3/envs/NodeSelection/lib/python3.10/site-packages/flwr/simulation/ray_transport/ray_client_proxy.py", line 215, in evaluate
    return maybe_call_evaluate(
  File "/opt/anaconda3/envs/NodeSelection/lib/python3.10/site-packages/flwr/client/client.py", line 237, in maybe_call_evaluate
    return client.evaluate(evaluate_ins)
  File "/opt/anaconda3/envs/NodeSelection/lib/python3.10/site-packages/flwr/client/app.py", line 357, in _evaluate
    results = self.numpy_client.evaluate(parameters, ins.config)  # type: ignore
  File "/Users/livialestingi/PycharmProjects/NodeSelection/power_of_choice/power_of_choice/client_ecto.py", line 90, in evaluate
    idx = np.random.choice(len(x_entire), b, replace=False)
  File "mtrand.pyx", line 984, in numpy.random.mtrand.RandomState.choice
ValueError: Cannot take a larger sample than population when 'replace=False'

The above exception was the direct cause of the following exception:

[36mray::DefaultActor.run()[39m (pid=15281, ip=127.0.0.1, actor_id=22a19f96bd8f8e9f9071114c01000000, repr=<flwr.simulation.ray_transport.ray_actor.DefaultActor object at 0x141180bb0>)
  File "/opt/anaconda3/envs/NodeSelection/lib/python3.10/site-packages/flwr/simulation/ray_transport/ray_actor.py", line 72, in run
    raise ClientException(str(message)) from ex
flwr.simulation.ray_transport.ray_actor.ClientException: 
>>>>>>>A ClientException occurred.('\n\tSomething went wrong when running your client workload.\n\tClient 0 crashed when the DefaultActor was running its workload.\n\tException triggered on the client side: Traceback (most recent call last):\n  File "/opt/anaconda3/envs/NodeSelection/lib/python3.10/site-packages/flwr/simulation/ray_transport/ray_actor.py", line 60, in run\n    job_results = job_fn()\n  File "/opt/anaconda3/envs/NodeSelection/lib/python3.10/site-packages/flwr/simulation/ray_transport/ray_client_proxy.py", line 215, in evaluate\n    return maybe_call_evaluate(\n  File "/opt/anaconda3/envs/NodeSelection/lib/python3.10/site-packages/flwr/client/client.py", line 237, in maybe_call_evaluate\n    return client.evaluate(evaluate_ins)\n  File "/opt/anaconda3/envs/NodeSelection/lib/python3.10/site-packages/flwr/client/app.py", line 357, in _evaluate\n    results = self.numpy_client.evaluate(parameters, ins.config)  # type: ignore\n  File "/Users/livialestingi/PycharmProjects/NodeSelection/power_of_choice/power_of_choice/client_ecto.py", line 90, in evaluate\n    idx = np.random.choice(len(x_entire), b, replace=False)\n  File "mtrand.pyx", line 984, in numpy.random.mtrand.RandomState.choice\nValueError: Cannot take a larger sample than population when \'replace=False\'\n',)

[2025-03-24 12:23:40,207][flwr][ERROR] - [36mray::DefaultActor.run()[39m (pid=15281, ip=127.0.0.1, actor_id=22a19f96bd8f8e9f9071114c01000000, repr=<flwr.simulation.ray_transport.ray_actor.DefaultActor object at 0x141180bb0>)
  File "/opt/anaconda3/envs/NodeSelection/lib/python3.10/site-packages/flwr/simulation/ray_transport/ray_client_proxy.py", line 215, in evaluate
    return maybe_call_evaluate(
  File "/opt/anaconda3/envs/NodeSelection/lib/python3.10/site-packages/flwr/client/client.py", line 237, in maybe_call_evaluate
    return client.evaluate(evaluate_ins)
  File "/opt/anaconda3/envs/NodeSelection/lib/python3.10/site-packages/flwr/client/app.py", line 357, in _evaluate
    results = self.numpy_client.evaluate(parameters, ins.config)  # type: ignore
  File "/Users/livialestingi/PycharmProjects/NodeSelection/power_of_choice/power_of_choice/client_ecto.py", line 90, in evaluate
    idx = np.random.choice(len(x_entire), b, replace=False)
  File "mtrand.pyx", line 984, in numpy.random.mtrand.RandomState.choice
ValueError: Cannot take a larger sample than population when 'replace=False'

The above exception was the direct cause of the following exception:

[36mray::DefaultActor.run()[39m (pid=15281, ip=127.0.0.1, actor_id=22a19f96bd8f8e9f9071114c01000000, repr=<flwr.simulation.ray_transport.ray_actor.DefaultActor object at 0x141180bb0>)
  File "/opt/anaconda3/envs/NodeSelection/lib/python3.10/site-packages/flwr/simulation/ray_transport/ray_actor.py", line 72, in run
    raise ClientException(str(message)) from ex
flwr.simulation.ray_transport.ray_actor.ClientException: 
>>>>>>>A ClientException occurred.('\n\tSomething went wrong when running your client workload.\n\tClient 0 crashed when the DefaultActor was running its workload.\n\tException triggered on the client side: Traceback (most recent call last):\n  File "/opt/anaconda3/envs/NodeSelection/lib/python3.10/site-packages/flwr/simulation/ray_transport/ray_actor.py", line 60, in run\n    job_results = job_fn()\n  File "/opt/anaconda3/envs/NodeSelection/lib/python3.10/site-packages/flwr/simulation/ray_transport/ray_client_proxy.py", line 215, in evaluate\n    return maybe_call_evaluate(\n  File "/opt/anaconda3/envs/NodeSelection/lib/python3.10/site-packages/flwr/client/client.py", line 237, in maybe_call_evaluate\n    return client.evaluate(evaluate_ins)\n  File "/opt/anaconda3/envs/NodeSelection/lib/python3.10/site-packages/flwr/client/app.py", line 357, in _evaluate\n    results = self.numpy_client.evaluate(parameters, ins.config)  # type: ignore\n  File "/Users/livialestingi/PycharmProjects/NodeSelection/power_of_choice/power_of_choice/client_ecto.py", line 90, in evaluate\n    idx = np.random.choice(len(x_entire), b, replace=False)\n  File "mtrand.pyx", line 984, in numpy.random.mtrand.RandomState.choice\nValueError: Cannot take a larger sample than population when \'replace=False\'\n',)
[2025-03-24 12:23:41,996][flwr][DEBUG] - evaluate_first_phase of round 12 received 9 results and 1 failures
[2025-03-24 12:23:41,996][flwr][INFO] - Server 12: about to sample 9 clients
[2025-03-24 12:23:41,996][flwr][INFO] - Round 12: selected clients
            ['8', '7', '2', '9', '1', '3', '6', '5', '4'] for fit.
[2025-03-24 12:23:41,996][flwr][DEBUG] - fit_round 12: strategy sampled 9 clients (out of 10)
[2025-03-24 12:23:59,789][flwr][DEBUG] - fit_round 12 received 9 results and 0 failures
[2025-03-24 12:24:00,992][flwr][INFO] - fit progress: (12, 1.5914429426193237, {'accuracy': 0.4505999982357025}, 305.9257539159953)
[2025-03-24 12:24:00,992][flwr][DEBUG] - evaluate_round 12: strategy sampled 9 clients (out of 10)
[2025-03-24 12:24:03,125][flwr][DEBUG] - evaluate_round 12 received 9 results and 0 failures
[2025-03-24 12:24:05,982][flwr][INFO] - Server 13: selected clients
                ['5', '3', '9', '2', '7', '1', '4', '6', '8', '0'] for first phase evaluation.
[2025-03-24 12:24:05,982][flwr][DEBUG] - evaluate_first_phase 13: strategy sampled 10 clients (out of 10)
[2025-03-24 12:24:06,320][flwr][ERROR] - Traceback (most recent call last):
  File "/opt/anaconda3/envs/NodeSelection/lib/python3.10/site-packages/flwr/simulation/ray_transport/ray_client_proxy.py", line 140, in _submit_job
    res = self.actor_pool.get_client_result(self.cid, timeout)
  File "/opt/anaconda3/envs/NodeSelection/lib/python3.10/site-packages/flwr/simulation/ray_transport/ray_actor.py", line 402, in get_client_result
    return self._fetch_future_result(cid)
  File "/opt/anaconda3/envs/NodeSelection/lib/python3.10/site-packages/flwr/simulation/ray_transport/ray_actor.py", line 288, in _fetch_future_result
    res_cid, res = ray.get(future)  # type: (str, ClientRes)
  File "/opt/anaconda3/envs/NodeSelection/lib/python3.10/site-packages/ray/_private/auto_init_hook.py", line 21, in auto_init_wrapper
    return fn(*args, **kwargs)
  File "/opt/anaconda3/envs/NodeSelection/lib/python3.10/site-packages/ray/_private/client_mode_hook.py", line 103, in wrapper
    return func(*args, **kwargs)
  File "/opt/anaconda3/envs/NodeSelection/lib/python3.10/site-packages/ray/_private/worker.py", line 2771, in get
    values, debugger_breakpoint = worker.get_objects(object_refs, timeout=timeout)
  File "/opt/anaconda3/envs/NodeSelection/lib/python3.10/site-packages/ray/_private/worker.py", line 919, in get_objects
    raise value.as_instanceof_cause()
ray.exceptions.RayTaskError(ClientException): [36mray::DefaultActor.run()[39m (pid=15281, ip=127.0.0.1, actor_id=22a19f96bd8f8e9f9071114c01000000, repr=<flwr.simulation.ray_transport.ray_actor.DefaultActor object at 0x141180bb0>)
  File "/opt/anaconda3/envs/NodeSelection/lib/python3.10/site-packages/flwr/simulation/ray_transport/ray_client_proxy.py", line 215, in evaluate
    return maybe_call_evaluate(
  File "/opt/anaconda3/envs/NodeSelection/lib/python3.10/site-packages/flwr/client/client.py", line 237, in maybe_call_evaluate
    return client.evaluate(evaluate_ins)
  File "/opt/anaconda3/envs/NodeSelection/lib/python3.10/site-packages/flwr/client/app.py", line 357, in _evaluate
    results = self.numpy_client.evaluate(parameters, ins.config)  # type: ignore
  File "/Users/livialestingi/PycharmProjects/NodeSelection/power_of_choice/power_of_choice/client_ecto.py", line 90, in evaluate
    idx = np.random.choice(len(x_entire), b, replace=False)
  File "mtrand.pyx", line 984, in numpy.random.mtrand.RandomState.choice
ValueError: Cannot take a larger sample than population when 'replace=False'

The above exception was the direct cause of the following exception:

[36mray::DefaultActor.run()[39m (pid=15281, ip=127.0.0.1, actor_id=22a19f96bd8f8e9f9071114c01000000, repr=<flwr.simulation.ray_transport.ray_actor.DefaultActor object at 0x141180bb0>)
  File "/opt/anaconda3/envs/NodeSelection/lib/python3.10/site-packages/flwr/simulation/ray_transport/ray_actor.py", line 72, in run
    raise ClientException(str(message)) from ex
flwr.simulation.ray_transport.ray_actor.ClientException: 
>>>>>>>A ClientException occurred.('\n\tSomething went wrong when running your client workload.\n\tClient 0 crashed when the DefaultActor was running its workload.\n\tException triggered on the client side: Traceback (most recent call last):\n  File "/opt/anaconda3/envs/NodeSelection/lib/python3.10/site-packages/flwr/simulation/ray_transport/ray_actor.py", line 60, in run\n    job_results = job_fn()\n  File "/opt/anaconda3/envs/NodeSelection/lib/python3.10/site-packages/flwr/simulation/ray_transport/ray_client_proxy.py", line 215, in evaluate\n    return maybe_call_evaluate(\n  File "/opt/anaconda3/envs/NodeSelection/lib/python3.10/site-packages/flwr/client/client.py", line 237, in maybe_call_evaluate\n    return client.evaluate(evaluate_ins)\n  File "/opt/anaconda3/envs/NodeSelection/lib/python3.10/site-packages/flwr/client/app.py", line 357, in _evaluate\n    results = self.numpy_client.evaluate(parameters, ins.config)  # type: ignore\n  File "/Users/livialestingi/PycharmProjects/NodeSelection/power_of_choice/power_of_choice/client_ecto.py", line 90, in evaluate\n    idx = np.random.choice(len(x_entire), b, replace=False)\n  File "mtrand.pyx", line 984, in numpy.random.mtrand.RandomState.choice\nValueError: Cannot take a larger sample than population when \'replace=False\'\n',)

[2025-03-24 12:24:06,323][flwr][ERROR] - [36mray::DefaultActor.run()[39m (pid=15281, ip=127.0.0.1, actor_id=22a19f96bd8f8e9f9071114c01000000, repr=<flwr.simulation.ray_transport.ray_actor.DefaultActor object at 0x141180bb0>)
  File "/opt/anaconda3/envs/NodeSelection/lib/python3.10/site-packages/flwr/simulation/ray_transport/ray_client_proxy.py", line 215, in evaluate
    return maybe_call_evaluate(
  File "/opt/anaconda3/envs/NodeSelection/lib/python3.10/site-packages/flwr/client/client.py", line 237, in maybe_call_evaluate
    return client.evaluate(evaluate_ins)
  File "/opt/anaconda3/envs/NodeSelection/lib/python3.10/site-packages/flwr/client/app.py", line 357, in _evaluate
    results = self.numpy_client.evaluate(parameters, ins.config)  # type: ignore
  File "/Users/livialestingi/PycharmProjects/NodeSelection/power_of_choice/power_of_choice/client_ecto.py", line 90, in evaluate
    idx = np.random.choice(len(x_entire), b, replace=False)
  File "mtrand.pyx", line 984, in numpy.random.mtrand.RandomState.choice
ValueError: Cannot take a larger sample than population when 'replace=False'

The above exception was the direct cause of the following exception:

[36mray::DefaultActor.run()[39m (pid=15281, ip=127.0.0.1, actor_id=22a19f96bd8f8e9f9071114c01000000, repr=<flwr.simulation.ray_transport.ray_actor.DefaultActor object at 0x141180bb0>)
  File "/opt/anaconda3/envs/NodeSelection/lib/python3.10/site-packages/flwr/simulation/ray_transport/ray_actor.py", line 72, in run
    raise ClientException(str(message)) from ex
flwr.simulation.ray_transport.ray_actor.ClientException: 
>>>>>>>A ClientException occurred.('\n\tSomething went wrong when running your client workload.\n\tClient 0 crashed when the DefaultActor was running its workload.\n\tException triggered on the client side: Traceback (most recent call last):\n  File "/opt/anaconda3/envs/NodeSelection/lib/python3.10/site-packages/flwr/simulation/ray_transport/ray_actor.py", line 60, in run\n    job_results = job_fn()\n  File "/opt/anaconda3/envs/NodeSelection/lib/python3.10/site-packages/flwr/simulation/ray_transport/ray_client_proxy.py", line 215, in evaluate\n    return maybe_call_evaluate(\n  File "/opt/anaconda3/envs/NodeSelection/lib/python3.10/site-packages/flwr/client/client.py", line 237, in maybe_call_evaluate\n    return client.evaluate(evaluate_ins)\n  File "/opt/anaconda3/envs/NodeSelection/lib/python3.10/site-packages/flwr/client/app.py", line 357, in _evaluate\n    results = self.numpy_client.evaluate(parameters, ins.config)  # type: ignore\n  File "/Users/livialestingi/PycharmProjects/NodeSelection/power_of_choice/power_of_choice/client_ecto.py", line 90, in evaluate\n    idx = np.random.choice(len(x_entire), b, replace=False)\n  File "mtrand.pyx", line 984, in numpy.random.mtrand.RandomState.choice\nValueError: Cannot take a larger sample than population when \'replace=False\'\n',)
[2025-03-24 12:24:08,163][flwr][DEBUG] - evaluate_first_phase of round 13 received 9 results and 1 failures
[2025-03-24 12:24:08,163][flwr][INFO] - Server 13: about to sample 9 clients
[2025-03-24 12:24:08,163][flwr][INFO] - Round 13: selected clients
            ['9', '3', '5', '2', '7', '6', '4', '1', '8'] for fit.
[2025-03-24 12:24:08,163][flwr][DEBUG] - fit_round 13: strategy sampled 9 clients (out of 10)
[2025-03-24 12:24:26,917][flwr][DEBUG] - fit_round 13 received 9 results and 0 failures
[2025-03-24 12:24:27,975][flwr][INFO] - fit progress: (13, 1.582289218902588, {'accuracy': 0.41929998993873596}, 332.9089907499947)
[2025-03-24 12:24:27,975][flwr][DEBUG] - evaluate_round 13: strategy sampled 9 clients (out of 10)
[2025-03-24 12:24:30,164][flwr][DEBUG] - evaluate_round 13 received 9 results and 0 failures
[2025-03-24 12:24:33,010][flwr][INFO] - Server 14: selected clients
                ['1', '6', '5', '4', '8', '9', '2', '3', '0', '7'] for first phase evaluation.
[2025-03-24 12:24:33,010][flwr][DEBUG] - evaluate_first_phase 14: strategy sampled 10 clients (out of 10)
[2025-03-24 12:24:33,242][flwr][ERROR] - Traceback (most recent call last):
  File "/opt/anaconda3/envs/NodeSelection/lib/python3.10/site-packages/flwr/simulation/ray_transport/ray_client_proxy.py", line 140, in _submit_job
    res = self.actor_pool.get_client_result(self.cid, timeout)
  File "/opt/anaconda3/envs/NodeSelection/lib/python3.10/site-packages/flwr/simulation/ray_transport/ray_actor.py", line 402, in get_client_result
    return self._fetch_future_result(cid)
  File "/opt/anaconda3/envs/NodeSelection/lib/python3.10/site-packages/flwr/simulation/ray_transport/ray_actor.py", line 288, in _fetch_future_result
    res_cid, res = ray.get(future)  # type: (str, ClientRes)
  File "/opt/anaconda3/envs/NodeSelection/lib/python3.10/site-packages/ray/_private/auto_init_hook.py", line 21, in auto_init_wrapper
    return fn(*args, **kwargs)
  File "/opt/anaconda3/envs/NodeSelection/lib/python3.10/site-packages/ray/_private/client_mode_hook.py", line 103, in wrapper
    return func(*args, **kwargs)
  File "/opt/anaconda3/envs/NodeSelection/lib/python3.10/site-packages/ray/_private/worker.py", line 2771, in get
    values, debugger_breakpoint = worker.get_objects(object_refs, timeout=timeout)
  File "/opt/anaconda3/envs/NodeSelection/lib/python3.10/site-packages/ray/_private/worker.py", line 919, in get_objects
    raise value.as_instanceof_cause()
ray.exceptions.RayTaskError(ClientException): [36mray::DefaultActor.run()[39m (pid=15292, ip=127.0.0.1, actor_id=dfb36b139064d62e0fd8fa6201000000, repr=<flwr.simulation.ray_transport.ray_actor.DefaultActor object at 0x161a80af0>)
  File "/opt/anaconda3/envs/NodeSelection/lib/python3.10/site-packages/flwr/simulation/ray_transport/ray_client_proxy.py", line 215, in evaluate
    return maybe_call_evaluate(
  File "/opt/anaconda3/envs/NodeSelection/lib/python3.10/site-packages/flwr/client/client.py", line 237, in maybe_call_evaluate
    return client.evaluate(evaluate_ins)
  File "/opt/anaconda3/envs/NodeSelection/lib/python3.10/site-packages/flwr/client/app.py", line 357, in _evaluate
    results = self.numpy_client.evaluate(parameters, ins.config)  # type: ignore
  File "/Users/livialestingi/PycharmProjects/NodeSelection/power_of_choice/power_of_choice/client_ecto.py", line 90, in evaluate
    idx = np.random.choice(len(x_entire), b, replace=False)
  File "mtrand.pyx", line 984, in numpy.random.mtrand.RandomState.choice
ValueError: Cannot take a larger sample than population when 'replace=False'

The above exception was the direct cause of the following exception:

[36mray::DefaultActor.run()[39m (pid=15292, ip=127.0.0.1, actor_id=dfb36b139064d62e0fd8fa6201000000, repr=<flwr.simulation.ray_transport.ray_actor.DefaultActor object at 0x161a80af0>)
  File "/opt/anaconda3/envs/NodeSelection/lib/python3.10/site-packages/flwr/simulation/ray_transport/ray_actor.py", line 72, in run
    raise ClientException(str(message)) from ex
flwr.simulation.ray_transport.ray_actor.ClientException: 
>>>>>>>A ClientException occurred.('\n\tSomething went wrong when running your client workload.\n\tClient 0 crashed when the DefaultActor was running its workload.\n\tException triggered on the client side: Traceback (most recent call last):\n  File "/opt/anaconda3/envs/NodeSelection/lib/python3.10/site-packages/flwr/simulation/ray_transport/ray_actor.py", line 60, in run\n    job_results = job_fn()\n  File "/opt/anaconda3/envs/NodeSelection/lib/python3.10/site-packages/flwr/simulation/ray_transport/ray_client_proxy.py", line 215, in evaluate\n    return maybe_call_evaluate(\n  File "/opt/anaconda3/envs/NodeSelection/lib/python3.10/site-packages/flwr/client/client.py", line 237, in maybe_call_evaluate\n    return client.evaluate(evaluate_ins)\n  File "/opt/anaconda3/envs/NodeSelection/lib/python3.10/site-packages/flwr/client/app.py", line 357, in _evaluate\n    results = self.numpy_client.evaluate(parameters, ins.config)  # type: ignore\n  File "/Users/livialestingi/PycharmProjects/NodeSelection/power_of_choice/power_of_choice/client_ecto.py", line 90, in evaluate\n    idx = np.random.choice(len(x_entire), b, replace=False)\n  File "mtrand.pyx", line 984, in numpy.random.mtrand.RandomState.choice\nValueError: Cannot take a larger sample than population when \'replace=False\'\n',)

[2025-03-24 12:24:33,245][flwr][ERROR] - [36mray::DefaultActor.run()[39m (pid=15292, ip=127.0.0.1, actor_id=dfb36b139064d62e0fd8fa6201000000, repr=<flwr.simulation.ray_transport.ray_actor.DefaultActor object at 0x161a80af0>)
  File "/opt/anaconda3/envs/NodeSelection/lib/python3.10/site-packages/flwr/simulation/ray_transport/ray_client_proxy.py", line 215, in evaluate
    return maybe_call_evaluate(
  File "/opt/anaconda3/envs/NodeSelection/lib/python3.10/site-packages/flwr/client/client.py", line 237, in maybe_call_evaluate
    return client.evaluate(evaluate_ins)
  File "/opt/anaconda3/envs/NodeSelection/lib/python3.10/site-packages/flwr/client/app.py", line 357, in _evaluate
    results = self.numpy_client.evaluate(parameters, ins.config)  # type: ignore
  File "/Users/livialestingi/PycharmProjects/NodeSelection/power_of_choice/power_of_choice/client_ecto.py", line 90, in evaluate
    idx = np.random.choice(len(x_entire), b, replace=False)
  File "mtrand.pyx", line 984, in numpy.random.mtrand.RandomState.choice
ValueError: Cannot take a larger sample than population when 'replace=False'

The above exception was the direct cause of the following exception:

[36mray::DefaultActor.run()[39m (pid=15292, ip=127.0.0.1, actor_id=dfb36b139064d62e0fd8fa6201000000, repr=<flwr.simulation.ray_transport.ray_actor.DefaultActor object at 0x161a80af0>)
  File "/opt/anaconda3/envs/NodeSelection/lib/python3.10/site-packages/flwr/simulation/ray_transport/ray_actor.py", line 72, in run
    raise ClientException(str(message)) from ex
flwr.simulation.ray_transport.ray_actor.ClientException: 
>>>>>>>A ClientException occurred.('\n\tSomething went wrong when running your client workload.\n\tClient 0 crashed when the DefaultActor was running its workload.\n\tException triggered on the client side: Traceback (most recent call last):\n  File "/opt/anaconda3/envs/NodeSelection/lib/python3.10/site-packages/flwr/simulation/ray_transport/ray_actor.py", line 60, in run\n    job_results = job_fn()\n  File "/opt/anaconda3/envs/NodeSelection/lib/python3.10/site-packages/flwr/simulation/ray_transport/ray_client_proxy.py", line 215, in evaluate\n    return maybe_call_evaluate(\n  File "/opt/anaconda3/envs/NodeSelection/lib/python3.10/site-packages/flwr/client/client.py", line 237, in maybe_call_evaluate\n    return client.evaluate(evaluate_ins)\n  File "/opt/anaconda3/envs/NodeSelection/lib/python3.10/site-packages/flwr/client/app.py", line 357, in _evaluate\n    results = self.numpy_client.evaluate(parameters, ins.config)  # type: ignore\n  File "/Users/livialestingi/PycharmProjects/NodeSelection/power_of_choice/power_of_choice/client_ecto.py", line 90, in evaluate\n    idx = np.random.choice(len(x_entire), b, replace=False)\n  File "mtrand.pyx", line 984, in numpy.random.mtrand.RandomState.choice\nValueError: Cannot take a larger sample than population when \'replace=False\'\n',)
[2025-03-24 12:24:35,086][flwr][DEBUG] - evaluate_first_phase of round 14 received 9 results and 1 failures
[2025-03-24 12:24:35,086][flwr][INFO] - Server 14: about to sample 9 clients
[2025-03-24 12:24:35,086][flwr][INFO] - Round 14: selected clients
            ['9', '1', '5', '4', '8', '2', '3', '6', '7'] for fit.
[2025-03-24 12:24:35,086][flwr][DEBUG] - fit_round 14: strategy sampled 9 clients (out of 10)
[2025-03-24 12:24:53,203][flwr][DEBUG] - fit_round 14 received 9 results and 0 failures
[2025-03-24 12:24:54,349][flwr][INFO] - fit progress: (14, 1.3772025108337402, {'accuracy': 0.5024999976158142}, 359.2831423749958)
[2025-03-24 12:24:54,349][flwr][DEBUG] - evaluate_round 14: strategy sampled 9 clients (out of 10)
[2025-03-24 12:24:56,515][flwr][DEBUG] - evaluate_round 14 received 9 results and 0 failures
[2025-03-24 12:24:59,325][flwr][INFO] - Server 15: selected clients
                ['3', '8', '2', '6', '9', '0', '5', '1', '4', '7'] for first phase evaluation.
[2025-03-24 12:24:59,325][flwr][DEBUG] - evaluate_first_phase 15: strategy sampled 10 clients (out of 10)
[2025-03-24 12:24:59,606][flwr][ERROR] - Traceback (most recent call last):
  File "/opt/anaconda3/envs/NodeSelection/lib/python3.10/site-packages/flwr/simulation/ray_transport/ray_client_proxy.py", line 140, in _submit_job
    res = self.actor_pool.get_client_result(self.cid, timeout)
  File "/opt/anaconda3/envs/NodeSelection/lib/python3.10/site-packages/flwr/simulation/ray_transport/ray_actor.py", line 402, in get_client_result
    return self._fetch_future_result(cid)
  File "/opt/anaconda3/envs/NodeSelection/lib/python3.10/site-packages/flwr/simulation/ray_transport/ray_actor.py", line 288, in _fetch_future_result
    res_cid, res = ray.get(future)  # type: (str, ClientRes)
  File "/opt/anaconda3/envs/NodeSelection/lib/python3.10/site-packages/ray/_private/auto_init_hook.py", line 21, in auto_init_wrapper
    return fn(*args, **kwargs)
  File "/opt/anaconda3/envs/NodeSelection/lib/python3.10/site-packages/ray/_private/client_mode_hook.py", line 103, in wrapper
    return func(*args, **kwargs)
  File "/opt/anaconda3/envs/NodeSelection/lib/python3.10/site-packages/ray/_private/worker.py", line 2771, in get
    values, debugger_breakpoint = worker.get_objects(object_refs, timeout=timeout)
  File "/opt/anaconda3/envs/NodeSelection/lib/python3.10/site-packages/ray/_private/worker.py", line 919, in get_objects
    raise value.as_instanceof_cause()
ray.exceptions.RayTaskError(ClientException): [36mray::DefaultActor.run()[39m (pid=15281, ip=127.0.0.1, actor_id=22a19f96bd8f8e9f9071114c01000000, repr=<flwr.simulation.ray_transport.ray_actor.DefaultActor object at 0x141180bb0>)
  File "/opt/anaconda3/envs/NodeSelection/lib/python3.10/site-packages/flwr/simulation/ray_transport/ray_client_proxy.py", line 215, in evaluate
    return maybe_call_evaluate(
  File "/opt/anaconda3/envs/NodeSelection/lib/python3.10/site-packages/flwr/client/client.py", line 237, in maybe_call_evaluate
    return client.evaluate(evaluate_ins)
  File "/opt/anaconda3/envs/NodeSelection/lib/python3.10/site-packages/flwr/client/app.py", line 357, in _evaluate
    results = self.numpy_client.evaluate(parameters, ins.config)  # type: ignore
  File "/Users/livialestingi/PycharmProjects/NodeSelection/power_of_choice/power_of_choice/client_ecto.py", line 90, in evaluate
    idx = np.random.choice(len(x_entire), b, replace=False)
  File "mtrand.pyx", line 984, in numpy.random.mtrand.RandomState.choice
ValueError: Cannot take a larger sample than population when 'replace=False'

The above exception was the direct cause of the following exception:

[36mray::DefaultActor.run()[39m (pid=15281, ip=127.0.0.1, actor_id=22a19f96bd8f8e9f9071114c01000000, repr=<flwr.simulation.ray_transport.ray_actor.DefaultActor object at 0x141180bb0>)
  File "/opt/anaconda3/envs/NodeSelection/lib/python3.10/site-packages/flwr/simulation/ray_transport/ray_actor.py", line 72, in run
    raise ClientException(str(message)) from ex
flwr.simulation.ray_transport.ray_actor.ClientException: 
>>>>>>>A ClientException occurred.('\n\tSomething went wrong when running your client workload.\n\tClient 0 crashed when the DefaultActor was running its workload.\n\tException triggered on the client side: Traceback (most recent call last):\n  File "/opt/anaconda3/envs/NodeSelection/lib/python3.10/site-packages/flwr/simulation/ray_transport/ray_actor.py", line 60, in run\n    job_results = job_fn()\n  File "/opt/anaconda3/envs/NodeSelection/lib/python3.10/site-packages/flwr/simulation/ray_transport/ray_client_proxy.py", line 215, in evaluate\n    return maybe_call_evaluate(\n  File "/opt/anaconda3/envs/NodeSelection/lib/python3.10/site-packages/flwr/client/client.py", line 237, in maybe_call_evaluate\n    return client.evaluate(evaluate_ins)\n  File "/opt/anaconda3/envs/NodeSelection/lib/python3.10/site-packages/flwr/client/app.py", line 357, in _evaluate\n    results = self.numpy_client.evaluate(parameters, ins.config)  # type: ignore\n  File "/Users/livialestingi/PycharmProjects/NodeSelection/power_of_choice/power_of_choice/client_ecto.py", line 90, in evaluate\n    idx = np.random.choice(len(x_entire), b, replace=False)\n  File "mtrand.pyx", line 984, in numpy.random.mtrand.RandomState.choice\nValueError: Cannot take a larger sample than population when \'replace=False\'\n',)

[2025-03-24 12:24:59,609][flwr][ERROR] - [36mray::DefaultActor.run()[39m (pid=15281, ip=127.0.0.1, actor_id=22a19f96bd8f8e9f9071114c01000000, repr=<flwr.simulation.ray_transport.ray_actor.DefaultActor object at 0x141180bb0>)
  File "/opt/anaconda3/envs/NodeSelection/lib/python3.10/site-packages/flwr/simulation/ray_transport/ray_client_proxy.py", line 215, in evaluate
    return maybe_call_evaluate(
  File "/opt/anaconda3/envs/NodeSelection/lib/python3.10/site-packages/flwr/client/client.py", line 237, in maybe_call_evaluate
    return client.evaluate(evaluate_ins)
  File "/opt/anaconda3/envs/NodeSelection/lib/python3.10/site-packages/flwr/client/app.py", line 357, in _evaluate
    results = self.numpy_client.evaluate(parameters, ins.config)  # type: ignore
  File "/Users/livialestingi/PycharmProjects/NodeSelection/power_of_choice/power_of_choice/client_ecto.py", line 90, in evaluate
    idx = np.random.choice(len(x_entire), b, replace=False)
  File "mtrand.pyx", line 984, in numpy.random.mtrand.RandomState.choice
ValueError: Cannot take a larger sample than population when 'replace=False'

The above exception was the direct cause of the following exception:

[36mray::DefaultActor.run()[39m (pid=15281, ip=127.0.0.1, actor_id=22a19f96bd8f8e9f9071114c01000000, repr=<flwr.simulation.ray_transport.ray_actor.DefaultActor object at 0x141180bb0>)
  File "/opt/anaconda3/envs/NodeSelection/lib/python3.10/site-packages/flwr/simulation/ray_transport/ray_actor.py", line 72, in run
    raise ClientException(str(message)) from ex
flwr.simulation.ray_transport.ray_actor.ClientException: 
>>>>>>>A ClientException occurred.('\n\tSomething went wrong when running your client workload.\n\tClient 0 crashed when the DefaultActor was running its workload.\n\tException triggered on the client side: Traceback (most recent call last):\n  File "/opt/anaconda3/envs/NodeSelection/lib/python3.10/site-packages/flwr/simulation/ray_transport/ray_actor.py", line 60, in run\n    job_results = job_fn()\n  File "/opt/anaconda3/envs/NodeSelection/lib/python3.10/site-packages/flwr/simulation/ray_transport/ray_client_proxy.py", line 215, in evaluate\n    return maybe_call_evaluate(\n  File "/opt/anaconda3/envs/NodeSelection/lib/python3.10/site-packages/flwr/client/client.py", line 237, in maybe_call_evaluate\n    return client.evaluate(evaluate_ins)\n  File "/opt/anaconda3/envs/NodeSelection/lib/python3.10/site-packages/flwr/client/app.py", line 357, in _evaluate\n    results = self.numpy_client.evaluate(parameters, ins.config)  # type: ignore\n  File "/Users/livialestingi/PycharmProjects/NodeSelection/power_of_choice/power_of_choice/client_ecto.py", line 90, in evaluate\n    idx = np.random.choice(len(x_entire), b, replace=False)\n  File "mtrand.pyx", line 984, in numpy.random.mtrand.RandomState.choice\nValueError: Cannot take a larger sample than population when \'replace=False\'\n',)
[2025-03-24 12:25:01,528][flwr][DEBUG] - evaluate_first_phase of round 15 received 9 results and 1 failures
[2025-03-24 12:25:01,528][flwr][INFO] - Server 15: about to sample 9 clients
[2025-03-24 12:25:01,528][flwr][INFO] - Round 15: selected clients
            ['8', '5', '4', '2', '7', '9', '3', '1', '6'] for fit.
[2025-03-24 12:25:01,528][flwr][DEBUG] - fit_round 15: strategy sampled 9 clients (out of 10)
[2025-03-24 12:25:19,223][flwr][DEBUG] - fit_round 15 received 9 results and 0 failures
[2025-03-24 12:25:20,271][flwr][INFO] - fit progress: (15, 1.3947817087173462, {'accuracy': 0.47279998660087585}, 385.2048085829956)
[2025-03-24 12:25:20,271][flwr][DEBUG] - evaluate_round 15: strategy sampled 9 clients (out of 10)
[2025-03-24 12:25:22,444][flwr][DEBUG] - evaluate_round 15 received 9 results and 0 failures
[2025-03-24 12:25:25,231][flwr][INFO] - Server 16: selected clients
                ['4', '9', '0', '7', '2', '8', '6', '5', '1', '3'] for first phase evaluation.
[2025-03-24 12:25:25,231][flwr][DEBUG] - evaluate_first_phase 16: strategy sampled 10 clients (out of 10)
[2025-03-24 12:25:25,379][flwr][ERROR] - Traceback (most recent call last):
  File "/opt/anaconda3/envs/NodeSelection/lib/python3.10/site-packages/flwr/simulation/ray_transport/ray_client_proxy.py", line 140, in _submit_job
    res = self.actor_pool.get_client_result(self.cid, timeout)
  File "/opt/anaconda3/envs/NodeSelection/lib/python3.10/site-packages/flwr/simulation/ray_transport/ray_actor.py", line 402, in get_client_result
    return self._fetch_future_result(cid)
  File "/opt/anaconda3/envs/NodeSelection/lib/python3.10/site-packages/flwr/simulation/ray_transport/ray_actor.py", line 288, in _fetch_future_result
    res_cid, res = ray.get(future)  # type: (str, ClientRes)
  File "/opt/anaconda3/envs/NodeSelection/lib/python3.10/site-packages/ray/_private/auto_init_hook.py", line 21, in auto_init_wrapper
    return fn(*args, **kwargs)
  File "/opt/anaconda3/envs/NodeSelection/lib/python3.10/site-packages/ray/_private/client_mode_hook.py", line 103, in wrapper
    return func(*args, **kwargs)
  File "/opt/anaconda3/envs/NodeSelection/lib/python3.10/site-packages/ray/_private/worker.py", line 2771, in get
    values, debugger_breakpoint = worker.get_objects(object_refs, timeout=timeout)
  File "/opt/anaconda3/envs/NodeSelection/lib/python3.10/site-packages/ray/_private/worker.py", line 919, in get_objects
    raise value.as_instanceof_cause()
ray.exceptions.RayTaskError(ClientException): [36mray::DefaultActor.run()[39m (pid=15288, ip=127.0.0.1, actor_id=ddad64d674d78daa40630f4d01000000, repr=<flwr.simulation.ray_transport.ray_actor.DefaultActor object at 0x160f7cb50>)
  File "/opt/anaconda3/envs/NodeSelection/lib/python3.10/site-packages/flwr/simulation/ray_transport/ray_client_proxy.py", line 215, in evaluate
    return maybe_call_evaluate(
  File "/opt/anaconda3/envs/NodeSelection/lib/python3.10/site-packages/flwr/client/client.py", line 237, in maybe_call_evaluate
    return client.evaluate(evaluate_ins)
  File "/opt/anaconda3/envs/NodeSelection/lib/python3.10/site-packages/flwr/client/app.py", line 357, in _evaluate
    results = self.numpy_client.evaluate(parameters, ins.config)  # type: ignore
  File "/Users/livialestingi/PycharmProjects/NodeSelection/power_of_choice/power_of_choice/client_ecto.py", line 90, in evaluate
    idx = np.random.choice(len(x_entire), b, replace=False)
  File "mtrand.pyx", line 984, in numpy.random.mtrand.RandomState.choice
ValueError: Cannot take a larger sample than population when 'replace=False'

The above exception was the direct cause of the following exception:

[36mray::DefaultActor.run()[39m (pid=15288, ip=127.0.0.1, actor_id=ddad64d674d78daa40630f4d01000000, repr=<flwr.simulation.ray_transport.ray_actor.DefaultActor object at 0x160f7cb50>)
  File "/opt/anaconda3/envs/NodeSelection/lib/python3.10/site-packages/flwr/simulation/ray_transport/ray_actor.py", line 72, in run
    raise ClientException(str(message)) from ex
flwr.simulation.ray_transport.ray_actor.ClientException: 
>>>>>>>A ClientException occurred.('\n\tSomething went wrong when running your client workload.\n\tClient 0 crashed when the DefaultActor was running its workload.\n\tException triggered on the client side: Traceback (most recent call last):\n  File "/opt/anaconda3/envs/NodeSelection/lib/python3.10/site-packages/flwr/simulation/ray_transport/ray_actor.py", line 60, in run\n    job_results = job_fn()\n  File "/opt/anaconda3/envs/NodeSelection/lib/python3.10/site-packages/flwr/simulation/ray_transport/ray_client_proxy.py", line 215, in evaluate\n    return maybe_call_evaluate(\n  File "/opt/anaconda3/envs/NodeSelection/lib/python3.10/site-packages/flwr/client/client.py", line 237, in maybe_call_evaluate\n    return client.evaluate(evaluate_ins)\n  File "/opt/anaconda3/envs/NodeSelection/lib/python3.10/site-packages/flwr/client/app.py", line 357, in _evaluate\n    results = self.numpy_client.evaluate(parameters, ins.config)  # type: ignore\n  File "/Users/livialestingi/PycharmProjects/NodeSelection/power_of_choice/power_of_choice/client_ecto.py", line 90, in evaluate\n    idx = np.random.choice(len(x_entire), b, replace=False)\n  File "mtrand.pyx", line 984, in numpy.random.mtrand.RandomState.choice\nValueError: Cannot take a larger sample than population when \'replace=False\'\n',)

[2025-03-24 12:25:25,383][flwr][ERROR] - [36mray::DefaultActor.run()[39m (pid=15288, ip=127.0.0.1, actor_id=ddad64d674d78daa40630f4d01000000, repr=<flwr.simulation.ray_transport.ray_actor.DefaultActor object at 0x160f7cb50>)
  File "/opt/anaconda3/envs/NodeSelection/lib/python3.10/site-packages/flwr/simulation/ray_transport/ray_client_proxy.py", line 215, in evaluate
    return maybe_call_evaluate(
  File "/opt/anaconda3/envs/NodeSelection/lib/python3.10/site-packages/flwr/client/client.py", line 237, in maybe_call_evaluate
    return client.evaluate(evaluate_ins)
  File "/opt/anaconda3/envs/NodeSelection/lib/python3.10/site-packages/flwr/client/app.py", line 357, in _evaluate
    results = self.numpy_client.evaluate(parameters, ins.config)  # type: ignore
  File "/Users/livialestingi/PycharmProjects/NodeSelection/power_of_choice/power_of_choice/client_ecto.py", line 90, in evaluate
    idx = np.random.choice(len(x_entire), b, replace=False)
  File "mtrand.pyx", line 984, in numpy.random.mtrand.RandomState.choice
ValueError: Cannot take a larger sample than population when 'replace=False'

The above exception was the direct cause of the following exception:

[36mray::DefaultActor.run()[39m (pid=15288, ip=127.0.0.1, actor_id=ddad64d674d78daa40630f4d01000000, repr=<flwr.simulation.ray_transport.ray_actor.DefaultActor object at 0x160f7cb50>)
  File "/opt/anaconda3/envs/NodeSelection/lib/python3.10/site-packages/flwr/simulation/ray_transport/ray_actor.py", line 72, in run
    raise ClientException(str(message)) from ex
flwr.simulation.ray_transport.ray_actor.ClientException: 
>>>>>>>A ClientException occurred.('\n\tSomething went wrong when running your client workload.\n\tClient 0 crashed when the DefaultActor was running its workload.\n\tException triggered on the client side: Traceback (most recent call last):\n  File "/opt/anaconda3/envs/NodeSelection/lib/python3.10/site-packages/flwr/simulation/ray_transport/ray_actor.py", line 60, in run\n    job_results = job_fn()\n  File "/opt/anaconda3/envs/NodeSelection/lib/python3.10/site-packages/flwr/simulation/ray_transport/ray_client_proxy.py", line 215, in evaluate\n    return maybe_call_evaluate(\n  File "/opt/anaconda3/envs/NodeSelection/lib/python3.10/site-packages/flwr/client/client.py", line 237, in maybe_call_evaluate\n    return client.evaluate(evaluate_ins)\n  File "/opt/anaconda3/envs/NodeSelection/lib/python3.10/site-packages/flwr/client/app.py", line 357, in _evaluate\n    results = self.numpy_client.evaluate(parameters, ins.config)  # type: ignore\n  File "/Users/livialestingi/PycharmProjects/NodeSelection/power_of_choice/power_of_choice/client_ecto.py", line 90, in evaluate\n    idx = np.random.choice(len(x_entire), b, replace=False)\n  File "mtrand.pyx", line 984, in numpy.random.mtrand.RandomState.choice\nValueError: Cannot take a larger sample than population when \'replace=False\'\n',)
[2025-03-24 12:25:27,134][flwr][DEBUG] - evaluate_first_phase of round 16 received 9 results and 1 failures
[2025-03-24 12:25:27,134][flwr][INFO] - Server 16: about to sample 9 clients
[2025-03-24 12:25:27,134][flwr][INFO] - Round 16: selected clients
            ['7', '4', '5', '8', '6', '2', '1', '9', '3'] for fit.
[2025-03-24 12:25:27,134][flwr][DEBUG] - fit_round 16: strategy sampled 9 clients (out of 10)
[2025-03-24 12:25:45,175][flwr][DEBUG] - fit_round 16 received 9 results and 0 failures
[2025-03-24 12:25:46,223][flwr][INFO] - fit progress: (16, 1.457373023033142, {'accuracy': 0.4636000096797943}, 411.1576607909956)
[2025-03-24 12:25:46,224][flwr][DEBUG] - evaluate_round 16: strategy sampled 9 clients (out of 10)
[2025-03-24 12:25:48,558][flwr][DEBUG] - evaluate_round 16 received 9 results and 0 failures
[2025-03-24 12:25:51,413][flwr][INFO] - Server 17: selected clients
                ['8', '4', '3', '6', '7', '1', '9', '0', '5', '2'] for first phase evaluation.
[2025-03-24 12:25:51,413][flwr][DEBUG] - evaluate_first_phase 17: strategy sampled 10 clients (out of 10)
[2025-03-24 12:25:51,664][flwr][ERROR] - Traceback (most recent call last):
  File "/opt/anaconda3/envs/NodeSelection/lib/python3.10/site-packages/flwr/simulation/ray_transport/ray_client_proxy.py", line 140, in _submit_job
    res = self.actor_pool.get_client_result(self.cid, timeout)
  File "/opt/anaconda3/envs/NodeSelection/lib/python3.10/site-packages/flwr/simulation/ray_transport/ray_actor.py", line 402, in get_client_result
    return self._fetch_future_result(cid)
  File "/opt/anaconda3/envs/NodeSelection/lib/python3.10/site-packages/flwr/simulation/ray_transport/ray_actor.py", line 288, in _fetch_future_result
    res_cid, res = ray.get(future)  # type: (str, ClientRes)
  File "/opt/anaconda3/envs/NodeSelection/lib/python3.10/site-packages/ray/_private/auto_init_hook.py", line 21, in auto_init_wrapper
    return fn(*args, **kwargs)
  File "/opt/anaconda3/envs/NodeSelection/lib/python3.10/site-packages/ray/_private/client_mode_hook.py", line 103, in wrapper
    return func(*args, **kwargs)
  File "/opt/anaconda3/envs/NodeSelection/lib/python3.10/site-packages/ray/_private/worker.py", line 2771, in get
    values, debugger_breakpoint = worker.get_objects(object_refs, timeout=timeout)
  File "/opt/anaconda3/envs/NodeSelection/lib/python3.10/site-packages/ray/_private/worker.py", line 919, in get_objects
    raise value.as_instanceof_cause()
ray.exceptions.RayTaskError(ClientException): [36mray::DefaultActor.run()[39m (pid=15291, ip=127.0.0.1, actor_id=5dbeb755feff7f475d2d71a901000000, repr=<flwr.simulation.ray_transport.ray_actor.DefaultActor object at 0x14437cb20>)
  File "/opt/anaconda3/envs/NodeSelection/lib/python3.10/site-packages/flwr/simulation/ray_transport/ray_client_proxy.py", line 215, in evaluate
    return maybe_call_evaluate(
  File "/opt/anaconda3/envs/NodeSelection/lib/python3.10/site-packages/flwr/client/client.py", line 237, in maybe_call_evaluate
    return client.evaluate(evaluate_ins)
  File "/opt/anaconda3/envs/NodeSelection/lib/python3.10/site-packages/flwr/client/app.py", line 357, in _evaluate
    results = self.numpy_client.evaluate(parameters, ins.config)  # type: ignore
  File "/Users/livialestingi/PycharmProjects/NodeSelection/power_of_choice/power_of_choice/client_ecto.py", line 90, in evaluate
    idx = np.random.choice(len(x_entire), b, replace=False)
  File "mtrand.pyx", line 984, in numpy.random.mtrand.RandomState.choice
ValueError: Cannot take a larger sample than population when 'replace=False'

The above exception was the direct cause of the following exception:

[36mray::DefaultActor.run()[39m (pid=15291, ip=127.0.0.1, actor_id=5dbeb755feff7f475d2d71a901000000, repr=<flwr.simulation.ray_transport.ray_actor.DefaultActor object at 0x14437cb20>)
  File "/opt/anaconda3/envs/NodeSelection/lib/python3.10/site-packages/flwr/simulation/ray_transport/ray_actor.py", line 72, in run
    raise ClientException(str(message)) from ex
flwr.simulation.ray_transport.ray_actor.ClientException: 
>>>>>>>A ClientException occurred.('\n\tSomething went wrong when running your client workload.\n\tClient 0 crashed when the DefaultActor was running its workload.\n\tException triggered on the client side: Traceback (most recent call last):\n  File "/opt/anaconda3/envs/NodeSelection/lib/python3.10/site-packages/flwr/simulation/ray_transport/ray_actor.py", line 60, in run\n    job_results = job_fn()\n  File "/opt/anaconda3/envs/NodeSelection/lib/python3.10/site-packages/flwr/simulation/ray_transport/ray_client_proxy.py", line 215, in evaluate\n    return maybe_call_evaluate(\n  File "/opt/anaconda3/envs/NodeSelection/lib/python3.10/site-packages/flwr/client/client.py", line 237, in maybe_call_evaluate\n    return client.evaluate(evaluate_ins)\n  File "/opt/anaconda3/envs/NodeSelection/lib/python3.10/site-packages/flwr/client/app.py", line 357, in _evaluate\n    results = self.numpy_client.evaluate(parameters, ins.config)  # type: ignore\n  File "/Users/livialestingi/PycharmProjects/NodeSelection/power_of_choice/power_of_choice/client_ecto.py", line 90, in evaluate\n    idx = np.random.choice(len(x_entire), b, replace=False)\n  File "mtrand.pyx", line 984, in numpy.random.mtrand.RandomState.choice\nValueError: Cannot take a larger sample than population when \'replace=False\'\n',)

[2025-03-24 12:25:51,667][flwr][ERROR] - [36mray::DefaultActor.run()[39m (pid=15291, ip=127.0.0.1, actor_id=5dbeb755feff7f475d2d71a901000000, repr=<flwr.simulation.ray_transport.ray_actor.DefaultActor object at 0x14437cb20>)
  File "/opt/anaconda3/envs/NodeSelection/lib/python3.10/site-packages/flwr/simulation/ray_transport/ray_client_proxy.py", line 215, in evaluate
    return maybe_call_evaluate(
  File "/opt/anaconda3/envs/NodeSelection/lib/python3.10/site-packages/flwr/client/client.py", line 237, in maybe_call_evaluate
    return client.evaluate(evaluate_ins)
  File "/opt/anaconda3/envs/NodeSelection/lib/python3.10/site-packages/flwr/client/app.py", line 357, in _evaluate
    results = self.numpy_client.evaluate(parameters, ins.config)  # type: ignore
  File "/Users/livialestingi/PycharmProjects/NodeSelection/power_of_choice/power_of_choice/client_ecto.py", line 90, in evaluate
    idx = np.random.choice(len(x_entire), b, replace=False)
  File "mtrand.pyx", line 984, in numpy.random.mtrand.RandomState.choice
ValueError: Cannot take a larger sample than population when 'replace=False'

The above exception was the direct cause of the following exception:

[36mray::DefaultActor.run()[39m (pid=15291, ip=127.0.0.1, actor_id=5dbeb755feff7f475d2d71a901000000, repr=<flwr.simulation.ray_transport.ray_actor.DefaultActor object at 0x14437cb20>)
  File "/opt/anaconda3/envs/NodeSelection/lib/python3.10/site-packages/flwr/simulation/ray_transport/ray_actor.py", line 72, in run
    raise ClientException(str(message)) from ex
flwr.simulation.ray_transport.ray_actor.ClientException: 
>>>>>>>A ClientException occurred.('\n\tSomething went wrong when running your client workload.\n\tClient 0 crashed when the DefaultActor was running its workload.\n\tException triggered on the client side: Traceback (most recent call last):\n  File "/opt/anaconda3/envs/NodeSelection/lib/python3.10/site-packages/flwr/simulation/ray_transport/ray_actor.py", line 60, in run\n    job_results = job_fn()\n  File "/opt/anaconda3/envs/NodeSelection/lib/python3.10/site-packages/flwr/simulation/ray_transport/ray_client_proxy.py", line 215, in evaluate\n    return maybe_call_evaluate(\n  File "/opt/anaconda3/envs/NodeSelection/lib/python3.10/site-packages/flwr/client/client.py", line 237, in maybe_call_evaluate\n    return client.evaluate(evaluate_ins)\n  File "/opt/anaconda3/envs/NodeSelection/lib/python3.10/site-packages/flwr/client/app.py", line 357, in _evaluate\n    results = self.numpy_client.evaluate(parameters, ins.config)  # type: ignore\n  File "/Users/livialestingi/PycharmProjects/NodeSelection/power_of_choice/power_of_choice/client_ecto.py", line 90, in evaluate\n    idx = np.random.choice(len(x_entire), b, replace=False)\n  File "mtrand.pyx", line 984, in numpy.random.mtrand.RandomState.choice\nValueError: Cannot take a larger sample than population when \'replace=False\'\n',)
[2025-03-24 12:25:53,318][flwr][DEBUG] - evaluate_first_phase of round 17 received 9 results and 1 failures
[2025-03-24 12:25:53,318][flwr][INFO] - Server 17: about to sample 9 clients
[2025-03-24 12:25:53,318][flwr][INFO] - Round 17: selected clients
            ['5', '1', '4', '8', '3', '6', '7', '9', '2'] for fit.
[2025-03-24 12:25:53,319][flwr][DEBUG] - fit_round 17: strategy sampled 9 clients (out of 10)
[2025-03-24 12:26:12,966][flwr][DEBUG] - fit_round 17 received 9 results and 0 failures
[2025-03-24 12:26:14,110][flwr][INFO] - fit progress: (17, 1.62409245967865, {'accuracy': 0.44359999895095825}, 439.0437948749968)
[2025-03-24 12:26:14,110][flwr][DEBUG] - evaluate_round 17: strategy sampled 9 clients (out of 10)
[2025-03-24 12:26:16,278][flwr][DEBUG] - evaluate_round 17 received 9 results and 0 failures
[2025-03-24 12:26:19,125][flwr][INFO] - Server 18: selected clients
                ['1', '9', '4', '7', '6', '2', '0', '3', '8', '5'] for first phase evaluation.
[2025-03-24 12:26:19,126][flwr][DEBUG] - evaluate_first_phase 18: strategy sampled 10 clients (out of 10)
[2025-03-24 12:26:19,392][flwr][ERROR] - Traceback (most recent call last):
  File "/opt/anaconda3/envs/NodeSelection/lib/python3.10/site-packages/flwr/simulation/ray_transport/ray_client_proxy.py", line 140, in _submit_job
    res = self.actor_pool.get_client_result(self.cid, timeout)
  File "/opt/anaconda3/envs/NodeSelection/lib/python3.10/site-packages/flwr/simulation/ray_transport/ray_actor.py", line 402, in get_client_result
    return self._fetch_future_result(cid)
  File "/opt/anaconda3/envs/NodeSelection/lib/python3.10/site-packages/flwr/simulation/ray_transport/ray_actor.py", line 288, in _fetch_future_result
    res_cid, res = ray.get(future)  # type: (str, ClientRes)
  File "/opt/anaconda3/envs/NodeSelection/lib/python3.10/site-packages/ray/_private/auto_init_hook.py", line 21, in auto_init_wrapper
    return fn(*args, **kwargs)
  File "/opt/anaconda3/envs/NodeSelection/lib/python3.10/site-packages/ray/_private/client_mode_hook.py", line 103, in wrapper
    return func(*args, **kwargs)
  File "/opt/anaconda3/envs/NodeSelection/lib/python3.10/site-packages/ray/_private/worker.py", line 2771, in get
    values, debugger_breakpoint = worker.get_objects(object_refs, timeout=timeout)
  File "/opt/anaconda3/envs/NodeSelection/lib/python3.10/site-packages/ray/_private/worker.py", line 919, in get_objects
    raise value.as_instanceof_cause()
ray.exceptions.RayTaskError(ClientException): [36mray::DefaultActor.run()[39m (pid=15284, ip=127.0.0.1, actor_id=948692ce9fb9c1e8140f598a01000000, repr=<flwr.simulation.ray_transport.ray_actor.DefaultActor object at 0x13a480a60>)
  File "/opt/anaconda3/envs/NodeSelection/lib/python3.10/site-packages/flwr/simulation/ray_transport/ray_client_proxy.py", line 215, in evaluate
    return maybe_call_evaluate(
  File "/opt/anaconda3/envs/NodeSelection/lib/python3.10/site-packages/flwr/client/client.py", line 237, in maybe_call_evaluate
    return client.evaluate(evaluate_ins)
  File "/opt/anaconda3/envs/NodeSelection/lib/python3.10/site-packages/flwr/client/app.py", line 357, in _evaluate
    results = self.numpy_client.evaluate(parameters, ins.config)  # type: ignore
  File "/Users/livialestingi/PycharmProjects/NodeSelection/power_of_choice/power_of_choice/client_ecto.py", line 90, in evaluate
    idx = np.random.choice(len(x_entire), b, replace=False)
  File "mtrand.pyx", line 984, in numpy.random.mtrand.RandomState.choice
ValueError: Cannot take a larger sample than population when 'replace=False'

The above exception was the direct cause of the following exception:

[36mray::DefaultActor.run()[39m (pid=15284, ip=127.0.0.1, actor_id=948692ce9fb9c1e8140f598a01000000, repr=<flwr.simulation.ray_transport.ray_actor.DefaultActor object at 0x13a480a60>)
  File "/opt/anaconda3/envs/NodeSelection/lib/python3.10/site-packages/flwr/simulation/ray_transport/ray_actor.py", line 72, in run
    raise ClientException(str(message)) from ex
flwr.simulation.ray_transport.ray_actor.ClientException: 
>>>>>>>A ClientException occurred.('\n\tSomething went wrong when running your client workload.\n\tClient 0 crashed when the DefaultActor was running its workload.\n\tException triggered on the client side: Traceback (most recent call last):\n  File "/opt/anaconda3/envs/NodeSelection/lib/python3.10/site-packages/flwr/simulation/ray_transport/ray_actor.py", line 60, in run\n    job_results = job_fn()\n  File "/opt/anaconda3/envs/NodeSelection/lib/python3.10/site-packages/flwr/simulation/ray_transport/ray_client_proxy.py", line 215, in evaluate\n    return maybe_call_evaluate(\n  File "/opt/anaconda3/envs/NodeSelection/lib/python3.10/site-packages/flwr/client/client.py", line 237, in maybe_call_evaluate\n    return client.evaluate(evaluate_ins)\n  File "/opt/anaconda3/envs/NodeSelection/lib/python3.10/site-packages/flwr/client/app.py", line 357, in _evaluate\n    results = self.numpy_client.evaluate(parameters, ins.config)  # type: ignore\n  File "/Users/livialestingi/PycharmProjects/NodeSelection/power_of_choice/power_of_choice/client_ecto.py", line 90, in evaluate\n    idx = np.random.choice(len(x_entire), b, replace=False)\n  File "mtrand.pyx", line 984, in numpy.random.mtrand.RandomState.choice\nValueError: Cannot take a larger sample than population when \'replace=False\'\n',)

[2025-03-24 12:26:19,395][flwr][ERROR] - [36mray::DefaultActor.run()[39m (pid=15284, ip=127.0.0.1, actor_id=948692ce9fb9c1e8140f598a01000000, repr=<flwr.simulation.ray_transport.ray_actor.DefaultActor object at 0x13a480a60>)
  File "/opt/anaconda3/envs/NodeSelection/lib/python3.10/site-packages/flwr/simulation/ray_transport/ray_client_proxy.py", line 215, in evaluate
    return maybe_call_evaluate(
  File "/opt/anaconda3/envs/NodeSelection/lib/python3.10/site-packages/flwr/client/client.py", line 237, in maybe_call_evaluate
    return client.evaluate(evaluate_ins)
  File "/opt/anaconda3/envs/NodeSelection/lib/python3.10/site-packages/flwr/client/app.py", line 357, in _evaluate
    results = self.numpy_client.evaluate(parameters, ins.config)  # type: ignore
  File "/Users/livialestingi/PycharmProjects/NodeSelection/power_of_choice/power_of_choice/client_ecto.py", line 90, in evaluate
    idx = np.random.choice(len(x_entire), b, replace=False)
  File "mtrand.pyx", line 984, in numpy.random.mtrand.RandomState.choice
ValueError: Cannot take a larger sample than population when 'replace=False'

The above exception was the direct cause of the following exception:

[36mray::DefaultActor.run()[39m (pid=15284, ip=127.0.0.1, actor_id=948692ce9fb9c1e8140f598a01000000, repr=<flwr.simulation.ray_transport.ray_actor.DefaultActor object at 0x13a480a60>)
  File "/opt/anaconda3/envs/NodeSelection/lib/python3.10/site-packages/flwr/simulation/ray_transport/ray_actor.py", line 72, in run
    raise ClientException(str(message)) from ex
flwr.simulation.ray_transport.ray_actor.ClientException: 
>>>>>>>A ClientException occurred.('\n\tSomething went wrong when running your client workload.\n\tClient 0 crashed when the DefaultActor was running its workload.\n\tException triggered on the client side: Traceback (most recent call last):\n  File "/opt/anaconda3/envs/NodeSelection/lib/python3.10/site-packages/flwr/simulation/ray_transport/ray_actor.py", line 60, in run\n    job_results = job_fn()\n  File "/opt/anaconda3/envs/NodeSelection/lib/python3.10/site-packages/flwr/simulation/ray_transport/ray_client_proxy.py", line 215, in evaluate\n    return maybe_call_evaluate(\n  File "/opt/anaconda3/envs/NodeSelection/lib/python3.10/site-packages/flwr/client/client.py", line 237, in maybe_call_evaluate\n    return client.evaluate(evaluate_ins)\n  File "/opt/anaconda3/envs/NodeSelection/lib/python3.10/site-packages/flwr/client/app.py", line 357, in _evaluate\n    results = self.numpy_client.evaluate(parameters, ins.config)  # type: ignore\n  File "/Users/livialestingi/PycharmProjects/NodeSelection/power_of_choice/power_of_choice/client_ecto.py", line 90, in evaluate\n    idx = np.random.choice(len(x_entire), b, replace=False)\n  File "mtrand.pyx", line 984, in numpy.random.mtrand.RandomState.choice\nValueError: Cannot take a larger sample than population when \'replace=False\'\n',)
[2025-03-24 12:26:21,268][flwr][DEBUG] - evaluate_first_phase of round 18 received 9 results and 1 failures
[2025-03-24 12:26:21,269][flwr][INFO] - Server 18: about to sample 9 clients
[2025-03-24 12:26:21,269][flwr][INFO] - Round 18: selected clients
            ['5', '6', '4', '7', '9', '8', '1', '3', '2'] for fit.
[2025-03-24 12:26:21,269][flwr][DEBUG] - fit_round 18: strategy sampled 9 clients (out of 10)
[2025-03-24 12:26:39,384][flwr][DEBUG] - fit_round 18 received 9 results and 0 failures
[2025-03-24 12:26:40,434][flwr][INFO] - fit progress: (18, 1.2289687395095825, {'accuracy': 0.5475000143051147}, 465.3685044159938)
[2025-03-24 12:26:40,434][flwr][DEBUG] - evaluate_round 18: strategy sampled 9 clients (out of 10)
[2025-03-24 12:26:42,505][flwr][DEBUG] - evaluate_round 18 received 9 results and 0 failures
[2025-03-24 12:26:45,340][flwr][INFO] - Server 19: selected clients
                ['3', '5', '2', '1', '4', '0', '7', '6', '9', '8'] for first phase evaluation.
[2025-03-24 12:26:45,340][flwr][DEBUG] - evaluate_first_phase 19: strategy sampled 10 clients (out of 10)
[2025-03-24 12:26:45,527][flwr][ERROR] - Traceback (most recent call last):
  File "/opt/anaconda3/envs/NodeSelection/lib/python3.10/site-packages/flwr/simulation/ray_transport/ray_client_proxy.py", line 140, in _submit_job
    res = self.actor_pool.get_client_result(self.cid, timeout)
  File "/opt/anaconda3/envs/NodeSelection/lib/python3.10/site-packages/flwr/simulation/ray_transport/ray_actor.py", line 402, in get_client_result
    return self._fetch_future_result(cid)
  File "/opt/anaconda3/envs/NodeSelection/lib/python3.10/site-packages/flwr/simulation/ray_transport/ray_actor.py", line 288, in _fetch_future_result
    res_cid, res = ray.get(future)  # type: (str, ClientRes)
  File "/opt/anaconda3/envs/NodeSelection/lib/python3.10/site-packages/ray/_private/auto_init_hook.py", line 21, in auto_init_wrapper
    return fn(*args, **kwargs)
  File "/opt/anaconda3/envs/NodeSelection/lib/python3.10/site-packages/ray/_private/client_mode_hook.py", line 103, in wrapper
    return func(*args, **kwargs)
  File "/opt/anaconda3/envs/NodeSelection/lib/python3.10/site-packages/ray/_private/worker.py", line 2771, in get
    values, debugger_breakpoint = worker.get_objects(object_refs, timeout=timeout)
  File "/opt/anaconda3/envs/NodeSelection/lib/python3.10/site-packages/ray/_private/worker.py", line 919, in get_objects
    raise value.as_instanceof_cause()
ray.exceptions.RayTaskError(ClientException): [36mray::DefaultActor.run()[39m (pid=15287, ip=127.0.0.1, actor_id=f01289fb297276cc0049796e01000000, repr=<flwr.simulation.ray_transport.ray_actor.DefaultActor object at 0x1637c4ac0>)
  File "/opt/anaconda3/envs/NodeSelection/lib/python3.10/site-packages/flwr/simulation/ray_transport/ray_client_proxy.py", line 215, in evaluate
    return maybe_call_evaluate(
  File "/opt/anaconda3/envs/NodeSelection/lib/python3.10/site-packages/flwr/client/client.py", line 237, in maybe_call_evaluate
    return client.evaluate(evaluate_ins)
  File "/opt/anaconda3/envs/NodeSelection/lib/python3.10/site-packages/flwr/client/app.py", line 357, in _evaluate
    results = self.numpy_client.evaluate(parameters, ins.config)  # type: ignore
  File "/Users/livialestingi/PycharmProjects/NodeSelection/power_of_choice/power_of_choice/client_ecto.py", line 90, in evaluate
    idx = np.random.choice(len(x_entire), b, replace=False)
  File "mtrand.pyx", line 984, in numpy.random.mtrand.RandomState.choice
ValueError: Cannot take a larger sample than population when 'replace=False'

The above exception was the direct cause of the following exception:

[36mray::DefaultActor.run()[39m (pid=15287, ip=127.0.0.1, actor_id=f01289fb297276cc0049796e01000000, repr=<flwr.simulation.ray_transport.ray_actor.DefaultActor object at 0x1637c4ac0>)
  File "/opt/anaconda3/envs/NodeSelection/lib/python3.10/site-packages/flwr/simulation/ray_transport/ray_actor.py", line 72, in run
    raise ClientException(str(message)) from ex
flwr.simulation.ray_transport.ray_actor.ClientException: 
>>>>>>>A ClientException occurred.('\n\tSomething went wrong when running your client workload.\n\tClient 0 crashed when the DefaultActor was running its workload.\n\tException triggered on the client side: Traceback (most recent call last):\n  File "/opt/anaconda3/envs/NodeSelection/lib/python3.10/site-packages/flwr/simulation/ray_transport/ray_actor.py", line 60, in run\n    job_results = job_fn()\n  File "/opt/anaconda3/envs/NodeSelection/lib/python3.10/site-packages/flwr/simulation/ray_transport/ray_client_proxy.py", line 215, in evaluate\n    return maybe_call_evaluate(\n  File "/opt/anaconda3/envs/NodeSelection/lib/python3.10/site-packages/flwr/client/client.py", line 237, in maybe_call_evaluate\n    return client.evaluate(evaluate_ins)\n  File "/opt/anaconda3/envs/NodeSelection/lib/python3.10/site-packages/flwr/client/app.py", line 357, in _evaluate\n    results = self.numpy_client.evaluate(parameters, ins.config)  # type: ignore\n  File "/Users/livialestingi/PycharmProjects/NodeSelection/power_of_choice/power_of_choice/client_ecto.py", line 90, in evaluate\n    idx = np.random.choice(len(x_entire), b, replace=False)\n  File "mtrand.pyx", line 984, in numpy.random.mtrand.RandomState.choice\nValueError: Cannot take a larger sample than population when \'replace=False\'\n',)

[2025-03-24 12:26:45,530][flwr][ERROR] - [36mray::DefaultActor.run()[39m (pid=15287, ip=127.0.0.1, actor_id=f01289fb297276cc0049796e01000000, repr=<flwr.simulation.ray_transport.ray_actor.DefaultActor object at 0x1637c4ac0>)
  File "/opt/anaconda3/envs/NodeSelection/lib/python3.10/site-packages/flwr/simulation/ray_transport/ray_client_proxy.py", line 215, in evaluate
    return maybe_call_evaluate(
  File "/opt/anaconda3/envs/NodeSelection/lib/python3.10/site-packages/flwr/client/client.py", line 237, in maybe_call_evaluate
    return client.evaluate(evaluate_ins)
  File "/opt/anaconda3/envs/NodeSelection/lib/python3.10/site-packages/flwr/client/app.py", line 357, in _evaluate
    results = self.numpy_client.evaluate(parameters, ins.config)  # type: ignore
  File "/Users/livialestingi/PycharmProjects/NodeSelection/power_of_choice/power_of_choice/client_ecto.py", line 90, in evaluate
    idx = np.random.choice(len(x_entire), b, replace=False)
  File "mtrand.pyx", line 984, in numpy.random.mtrand.RandomState.choice
ValueError: Cannot take a larger sample than population when 'replace=False'

The above exception was the direct cause of the following exception:

[36mray::DefaultActor.run()[39m (pid=15287, ip=127.0.0.1, actor_id=f01289fb297276cc0049796e01000000, repr=<flwr.simulation.ray_transport.ray_actor.DefaultActor object at 0x1637c4ac0>)
  File "/opt/anaconda3/envs/NodeSelection/lib/python3.10/site-packages/flwr/simulation/ray_transport/ray_actor.py", line 72, in run
    raise ClientException(str(message)) from ex
flwr.simulation.ray_transport.ray_actor.ClientException: 
>>>>>>>A ClientException occurred.('\n\tSomething went wrong when running your client workload.\n\tClient 0 crashed when the DefaultActor was running its workload.\n\tException triggered on the client side: Traceback (most recent call last):\n  File "/opt/anaconda3/envs/NodeSelection/lib/python3.10/site-packages/flwr/simulation/ray_transport/ray_actor.py", line 60, in run\n    job_results = job_fn()\n  File "/opt/anaconda3/envs/NodeSelection/lib/python3.10/site-packages/flwr/simulation/ray_transport/ray_client_proxy.py", line 215, in evaluate\n    return maybe_call_evaluate(\n  File "/opt/anaconda3/envs/NodeSelection/lib/python3.10/site-packages/flwr/client/client.py", line 237, in maybe_call_evaluate\n    return client.evaluate(evaluate_ins)\n  File "/opt/anaconda3/envs/NodeSelection/lib/python3.10/site-packages/flwr/client/app.py", line 357, in _evaluate\n    results = self.numpy_client.evaluate(parameters, ins.config)  # type: ignore\n  File "/Users/livialestingi/PycharmProjects/NodeSelection/power_of_choice/power_of_choice/client_ecto.py", line 90, in evaluate\n    idx = np.random.choice(len(x_entire), b, replace=False)\n  File "mtrand.pyx", line 984, in numpy.random.mtrand.RandomState.choice\nValueError: Cannot take a larger sample than population when \'replace=False\'\n',)
[2025-03-24 12:26:47,328][flwr][DEBUG] - evaluate_first_phase of round 19 received 9 results and 1 failures
[2025-03-24 12:26:47,329][flwr][INFO] - Server 19: about to sample 9 clients
[2025-03-24 12:26:47,329][flwr][INFO] - Round 19: selected clients
            ['8', '9', '1', '4', '2', '3', '5', '6', '7'] for fit.
[2025-03-24 12:26:47,329][flwr][DEBUG] - fit_round 19: strategy sampled 9 clients (out of 10)
[2025-03-24 12:27:05,731][flwr][DEBUG] - fit_round 19 received 9 results and 0 failures
[2025-03-24 12:27:06,760][flwr][INFO] - fit progress: (19, 1.2108123302459717, {'accuracy': 0.5557000041007996}, 491.69472458299424)
[2025-03-24 12:27:06,761][flwr][DEBUG] - evaluate_round 19: strategy sampled 9 clients (out of 10)
[2025-03-24 12:27:08,920][flwr][DEBUG] - evaluate_round 19 received 9 results and 0 failures
[2025-03-24 12:27:11,701][flwr][INFO] - Server 20: selected clients
                ['3', '0', '7', '5', '1', '9', '2', '4', '6', '8'] for first phase evaluation.
[2025-03-24 12:27:11,701][flwr][DEBUG] - evaluate_first_phase 20: strategy sampled 10 clients (out of 10)
[2025-03-24 12:27:11,854][flwr][ERROR] - Traceback (most recent call last):
  File "/opt/anaconda3/envs/NodeSelection/lib/python3.10/site-packages/flwr/simulation/ray_transport/ray_client_proxy.py", line 140, in _submit_job
    res = self.actor_pool.get_client_result(self.cid, timeout)
  File "/opt/anaconda3/envs/NodeSelection/lib/python3.10/site-packages/flwr/simulation/ray_transport/ray_actor.py", line 402, in get_client_result
    return self._fetch_future_result(cid)
  File "/opt/anaconda3/envs/NodeSelection/lib/python3.10/site-packages/flwr/simulation/ray_transport/ray_actor.py", line 288, in _fetch_future_result
    res_cid, res = ray.get(future)  # type: (str, ClientRes)
  File "/opt/anaconda3/envs/NodeSelection/lib/python3.10/site-packages/ray/_private/auto_init_hook.py", line 21, in auto_init_wrapper
    return fn(*args, **kwargs)
  File "/opt/anaconda3/envs/NodeSelection/lib/python3.10/site-packages/ray/_private/client_mode_hook.py", line 103, in wrapper
    return func(*args, **kwargs)
  File "/opt/anaconda3/envs/NodeSelection/lib/python3.10/site-packages/ray/_private/worker.py", line 2771, in get
    values, debugger_breakpoint = worker.get_objects(object_refs, timeout=timeout)
  File "/opt/anaconda3/envs/NodeSelection/lib/python3.10/site-packages/ray/_private/worker.py", line 919, in get_objects
    raise value.as_instanceof_cause()
ray.exceptions.RayTaskError(ClientException): [36mray::DefaultActor.run()[39m (pid=15290, ip=127.0.0.1, actor_id=215d376e3d427ab83626413401000000, repr=<flwr.simulation.ray_transport.ray_actor.DefaultActor object at 0x139f80b80>)
  File "/opt/anaconda3/envs/NodeSelection/lib/python3.10/site-packages/flwr/simulation/ray_transport/ray_client_proxy.py", line 215, in evaluate
    return maybe_call_evaluate(
  File "/opt/anaconda3/envs/NodeSelection/lib/python3.10/site-packages/flwr/client/client.py", line 237, in maybe_call_evaluate
    return client.evaluate(evaluate_ins)
  File "/opt/anaconda3/envs/NodeSelection/lib/python3.10/site-packages/flwr/client/app.py", line 357, in _evaluate
    results = self.numpy_client.evaluate(parameters, ins.config)  # type: ignore
  File "/Users/livialestingi/PycharmProjects/NodeSelection/power_of_choice/power_of_choice/client_ecto.py", line 90, in evaluate
    idx = np.random.choice(len(x_entire), b, replace=False)
  File "mtrand.pyx", line 984, in numpy.random.mtrand.RandomState.choice
ValueError: Cannot take a larger sample than population when 'replace=False'

The above exception was the direct cause of the following exception:

[36mray::DefaultActor.run()[39m (pid=15290, ip=127.0.0.1, actor_id=215d376e3d427ab83626413401000000, repr=<flwr.simulation.ray_transport.ray_actor.DefaultActor object at 0x139f80b80>)
  File "/opt/anaconda3/envs/NodeSelection/lib/python3.10/site-packages/flwr/simulation/ray_transport/ray_actor.py", line 72, in run
    raise ClientException(str(message)) from ex
flwr.simulation.ray_transport.ray_actor.ClientException: 
>>>>>>>A ClientException occurred.('\n\tSomething went wrong when running your client workload.\n\tClient 0 crashed when the DefaultActor was running its workload.\n\tException triggered on the client side: Traceback (most recent call last):\n  File "/opt/anaconda3/envs/NodeSelection/lib/python3.10/site-packages/flwr/simulation/ray_transport/ray_actor.py", line 60, in run\n    job_results = job_fn()\n  File "/opt/anaconda3/envs/NodeSelection/lib/python3.10/site-packages/flwr/simulation/ray_transport/ray_client_proxy.py", line 215, in evaluate\n    return maybe_call_evaluate(\n  File "/opt/anaconda3/envs/NodeSelection/lib/python3.10/site-packages/flwr/client/client.py", line 237, in maybe_call_evaluate\n    return client.evaluate(evaluate_ins)\n  File "/opt/anaconda3/envs/NodeSelection/lib/python3.10/site-packages/flwr/client/app.py", line 357, in _evaluate\n    results = self.numpy_client.evaluate(parameters, ins.config)  # type: ignore\n  File "/Users/livialestingi/PycharmProjects/NodeSelection/power_of_choice/power_of_choice/client_ecto.py", line 90, in evaluate\n    idx = np.random.choice(len(x_entire), b, replace=False)\n  File "mtrand.pyx", line 984, in numpy.random.mtrand.RandomState.choice\nValueError: Cannot take a larger sample than population when \'replace=False\'\n',)

[2025-03-24 12:27:11,857][flwr][ERROR] - [36mray::DefaultActor.run()[39m (pid=15290, ip=127.0.0.1, actor_id=215d376e3d427ab83626413401000000, repr=<flwr.simulation.ray_transport.ray_actor.DefaultActor object at 0x139f80b80>)
  File "/opt/anaconda3/envs/NodeSelection/lib/python3.10/site-packages/flwr/simulation/ray_transport/ray_client_proxy.py", line 215, in evaluate
    return maybe_call_evaluate(
  File "/opt/anaconda3/envs/NodeSelection/lib/python3.10/site-packages/flwr/client/client.py", line 237, in maybe_call_evaluate
    return client.evaluate(evaluate_ins)
  File "/opt/anaconda3/envs/NodeSelection/lib/python3.10/site-packages/flwr/client/app.py", line 357, in _evaluate
    results = self.numpy_client.evaluate(parameters, ins.config)  # type: ignore
  File "/Users/livialestingi/PycharmProjects/NodeSelection/power_of_choice/power_of_choice/client_ecto.py", line 90, in evaluate
    idx = np.random.choice(len(x_entire), b, replace=False)
  File "mtrand.pyx", line 984, in numpy.random.mtrand.RandomState.choice
ValueError: Cannot take a larger sample than population when 'replace=False'

The above exception was the direct cause of the following exception:

[36mray::DefaultActor.run()[39m (pid=15290, ip=127.0.0.1, actor_id=215d376e3d427ab83626413401000000, repr=<flwr.simulation.ray_transport.ray_actor.DefaultActor object at 0x139f80b80>)
  File "/opt/anaconda3/envs/NodeSelection/lib/python3.10/site-packages/flwr/simulation/ray_transport/ray_actor.py", line 72, in run
    raise ClientException(str(message)) from ex
flwr.simulation.ray_transport.ray_actor.ClientException: 
>>>>>>>A ClientException occurred.('\n\tSomething went wrong when running your client workload.\n\tClient 0 crashed when the DefaultActor was running its workload.\n\tException triggered on the client side: Traceback (most recent call last):\n  File "/opt/anaconda3/envs/NodeSelection/lib/python3.10/site-packages/flwr/simulation/ray_transport/ray_actor.py", line 60, in run\n    job_results = job_fn()\n  File "/opt/anaconda3/envs/NodeSelection/lib/python3.10/site-packages/flwr/simulation/ray_transport/ray_client_proxy.py", line 215, in evaluate\n    return maybe_call_evaluate(\n  File "/opt/anaconda3/envs/NodeSelection/lib/python3.10/site-packages/flwr/client/client.py", line 237, in maybe_call_evaluate\n    return client.evaluate(evaluate_ins)\n  File "/opt/anaconda3/envs/NodeSelection/lib/python3.10/site-packages/flwr/client/app.py", line 357, in _evaluate\n    results = self.numpy_client.evaluate(parameters, ins.config)  # type: ignore\n  File "/Users/livialestingi/PycharmProjects/NodeSelection/power_of_choice/power_of_choice/client_ecto.py", line 90, in evaluate\n    idx = np.random.choice(len(x_entire), b, replace=False)\n  File "mtrand.pyx", line 984, in numpy.random.mtrand.RandomState.choice\nValueError: Cannot take a larger sample than population when \'replace=False\'\n',)
[2025-03-24 12:27:13,629][flwr][DEBUG] - evaluate_first_phase of round 20 received 9 results and 1 failures
[2025-03-24 12:27:13,629][flwr][INFO] - Server 20: about to sample 9 clients
[2025-03-24 12:27:13,630][flwr][INFO] - Round 20: selected clients
            ['7', '4', '9', '5', '2', '3', '8', '1', '6'] for fit.
[2025-03-24 12:27:13,630][flwr][DEBUG] - fit_round 20: strategy sampled 9 clients (out of 10)
[2025-03-24 12:27:34,082][flwr][DEBUG] - fit_round 20 received 9 results and 0 failures
[2025-03-24 12:27:35,256][flwr][INFO] - fit progress: (20, 1.4031189680099487, {'accuracy': 0.46709999442100525}, 520.1898918749939)
[2025-03-24 12:27:35,256][flwr][DEBUG] - evaluate_round 20: strategy sampled 9 clients (out of 10)
[2025-03-24 12:27:37,447][flwr][DEBUG] - evaluate_round 20 received 9 results and 0 failures
[2025-03-24 12:27:37,447][flwr][INFO] - FL finished in 522.3816768749966
[2025-03-24 12:27:37,448][flwr][INFO] - app_fit: losses_distributed [(1, 2.4762244396617725), (2, 2.0573804958111666), (3, 1.7589612134882375), (4, 2.3894943084205833), (5, 2.052565298095697), (6, 2.2783803780619407), (7, 1.6102638937672917), (8, 1.5358244876583211), (9, 1.4547426533765766), (10, 1.6025342893142884), (11, 1.4582544683409138), (12, 1.8924261156628963), (13, 1.6298095628958804), (14, 1.5614402878527545), (15, 1.4416919371834853), (16, 1.4678587719041412), (17, 1.733612803877091), (18, 1.337638785771397), (19, 1.1913317831837145), (20, 1.6175711571526785)]
[2025-03-24 12:27:37,448][flwr][INFO] - app_fit: metrics_distributed_fit {'variance_training_loss': [(1, 0.19708325427712858), (2, 0.03852914460045377), (3, 0.02894806888257349), (4, 0.027120601067701675), (5, 0.03443306611637177), (6, 0.03159807908316614), (7, 0.04505280849783983), (8, 0.032791332475277185), (9, 0.03153557125727203), (10, 0.030544533697922007), (11, 0.04749287965047471), (12, 0.03199245498800312), (13, 0.024861338037500975), (14, 0.032861658536344374), (15, 0.03783209600304869), (16, 0.039131455494450997), (17, 0.03491814437492104), (18, 0.033312672817200135), (19, 0.03299613543453164), (20, 0.03813630480988756)], 'average_training_loss': [(1, 1.7638424502478705), (2, 1.4792552789052327), (3, 1.4190089835060968), (4, 1.3884988493389554), (5, 1.3743058443069458), (6, 1.335822171635098), (7, 1.3460830450057983), (8, 1.297298464510176), (9, 1.266778462462955), (10, 1.263237476348877), (11, 1.2752445605066087), (12, 1.236507256825765), (13, 1.1892057259877522), (14, 1.2083764804734125), (15, 1.2094727092319064), (16, 1.2049875060717266), (17, 1.191563606262207), (18, 1.1750687559445698), (19, 1.161809265613556), (20, 1.1633023884561327)], 'estimated_times': [(1, [68.59202726295011, 104.52210836482371, 0.6704607769876115, 8.898101341197744, 3.5726821079070166, 7.8527227171758085, 1.1925953360551313, 0.24130638726606238, 3.5357852196338895]), (2, [68.59202726295011, 3.5357852196338895, 8.898101341197744, 1.1925953360551313, 104.52210836482371, 0.6704607769876115, 0.24130638726606238, 7.8527227171758085, 3.5726821079070166]), (3, [3.5726821079070166, 7.8527227171758085, 0.6704607769876115, 68.59202726295011, 104.52210836482371, 1.1925953360551313, 3.5357852196338895, 8.898101341197744, 0.24130638726606238]), (4, [0.24130638726606238, 7.8527227171758085, 1.1925953360551313, 8.898101341197744, 104.52210836482371, 3.5726821079070166, 68.59202726295011, 0.6704607769876115, 3.5357852196338895]), (5, [104.52210836482371, 68.59202726295011, 1.1925953360551313, 0.6704607769876115, 0.24130638726606238, 3.5726821079070166, 7.8527227171758085, 3.5357852196338895, 8.898101341197744]), (6, [0.24130638726606238, 7.8527227171758085, 3.5357852196338895, 68.59202726295011, 0.6704607769876115, 1.1925953360551313, 104.52210836482371, 3.5726821079070166, 8.898101341197744]), (7, [8.898101341197744, 7.8527227171758085, 1.1925953360551313, 104.52210836482371, 0.24130638726606238, 68.59202726295011, 3.5726821079070166, 0.6704607769876115, 3.5357852196338895]), (8, [68.59202726295011, 7.8527227171758085, 0.6704607769876115, 0.24130638726606238, 3.5357852196338895, 8.898101341197744, 3.5726821079070166, 104.52210836482371, 1.1925953360551313]), (9, [0.6704607769876115, 1.1925953360551313, 8.898101341197744, 3.5357852196338895, 3.5726821079070166, 104.52210836482371, 0.24130638726606238, 7.8527227171758085, 68.59202726295011]), (10, [68.59202726295011, 8.898101341197744, 3.5726821079070166, 3.5357852196338895, 0.24130638726606238, 7.8527227171758085, 104.52210836482371, 0.6704607769876115, 1.1925953360551313]), (11, [8.898101341197744, 3.5726821079070166, 0.24130638726606238, 104.52210836482371, 3.5357852196338895, 1.1925953360551313, 0.6704607769876115, 7.8527227171758085, 68.59202726295011]), (12, [0.24130638726606238, 7.8527227171758085, 0.6704607769876115, 104.52210836482371, 3.5357852196338895, 8.898101341197744, 3.5726821079070166, 1.1925953360551313, 68.59202726295011]), (13, [0.6704607769876115, 3.5726821079070166, 1.1925953360551313, 8.898101341197744, 3.5357852196338895, 68.59202726295011, 0.24130638726606238, 104.52210836482371, 7.8527227171758085]), (14, [68.59202726295011, 0.6704607769876115, 1.1925953360551313, 3.5726821079070166, 8.898101341197744, 7.8527227171758085, 0.24130638726606238, 3.5357852196338895, 104.52210836482371]), (15, [3.5357852196338895, 0.6704607769876115, 104.52210836482371, 3.5726821079070166, 68.59202726295011, 0.24130638726606238, 8.898101341197744, 7.8527227171758085, 1.1925953360551313]), (16, [8.898101341197744, 7.8527227171758085, 68.59202726295011, 3.5357852196338895, 0.6704607769876115, 3.5726821079070166, 104.52210836482371, 0.24130638726606238, 1.1925953360551313]), (17, [1.1925953360551313, 8.898101341197744, 0.24130638726606238, 3.5357852196338895, 104.52210836482371, 0.6704607769876115, 68.59202726295011, 3.5726821079070166, 7.8527227171758085]), (18, [0.24130638726606238, 104.52210836482371, 3.5726821079070166, 7.8527227171758085, 1.1925953360551313, 8.898101341197744, 0.6704607769876115, 3.5357852196338895, 68.59202726295011]), (19, [0.24130638726606238, 104.52210836482371, 3.5357852196338895, 8.898101341197744, 0.6704607769876115, 68.59202726295011, 3.5726821079070166, 7.8527227171758085, 1.1925953360551313]), (20, [68.59202726295011, 0.24130638726606238, 0.6704607769876115, 7.8527227171758085, 8.898101341197744, 104.52210836482371, 1.1925953360551313, 3.5357852196338895, 3.5726821079070166])]}
[2025-03-24 12:27:37,450][flwr][INFO] - app_fit: metrics_distributed {}
[2025-03-24 12:27:37,450][flwr][INFO] - app_fit: losses_centralized [(0, 2.305549144744873), (1, 2.385333299636841), (2, 2.0079753398895264), (3, 1.6786978244781494), (4, 2.144805669784546), (5, 1.8693904876708984), (6, 2.543081760406494), (7, 1.535627007484436), (8, 1.4188491106033325), (9, 1.5399237871170044), (10, 1.622155785560608), (11, 1.4801506996154785), (12, 1.5914429426193237), (13, 1.582289218902588), (14, 1.3772025108337402), (15, 1.3947817087173462), (16, 1.457373023033142), (17, 1.62409245967865), (18, 1.2289687395095825), (19, 1.2108123302459717), (20, 1.4031189680099487)]
[2025-03-24 12:27:37,450][flwr][INFO] - app_fit: metrics_centralized {'accuracy': [(0, 0.10000000149011612), (1, 0.10040000081062317), (2, 0.22509999573230743), (3, 0.3880000114440918), (4, 0.23160000145435333), (5, 0.3174999952316284), (6, 0.22020000219345093), (7, 0.42250001430511475), (8, 0.487199991941452), (9, 0.43810001015663147), (10, 0.41530001163482666), (11, 0.45419999957084656), (12, 0.4505999982357025), (13, 0.41929998993873596), (14, 0.5024999976158142), (15, 0.47279998660087585), (16, 0.4636000096797943), (17, 0.44359999895095825), (18, 0.5475000143051147), (19, 0.5557000041007996), (20, 0.46709999442100525)]}
